Workbook

Sheet Notes
A1: Formula-driven version of dsm_metrics.xlsx: only the run matrices (data/experiments.txt), the ground truths and the eigenvalues are pasted; every metric is a spreadsheet formula.
A2: TP/TN/FP/FN = SUMPRODUCT((M=v)*(G=w)), so unsure cells (2) drop out of the confident-only counts; P/R/F1/Acc = IFERROR(ratio, 0); edit distance = SUMPRODUCT(ABS(G−M)) with the 2s kept; spectral distance = SQRT(SUMPRODUCT((eigG−eigM)^2)) over LARGE()-sorted eigenvalues; mean/std = AVERAGE/STDEV.P over the runs.
A3: Eigenvalues cannot be produced by built-in spreadsheet functions, so they are pasted (real parts, numpy order) and verified in-sheet: Σeig − trace and Πeig − det must be 0, and det(M − λI) = 0 per eigenvalue via MDETERM/MUNIT. Matrices with complex eigenvalues are marked; the real parts are used, and Πeig − det does not apply to them.
A4: The Step2 average matrix is a per-cell formula (2 if no confident run, else 1 if the mean of the confident runs ≥ 0.5, else 0); the 'avg-matrix' columns evaluate the metrics once on it. The paper reports the per-run mean ± std.
A5: A configuration with four matrices in experiments.txt had one run that returned no matrix; its values are the mean ± std of the four runs present (see the note column).
A6: Task (ii) aligned sheets build the k×k aligned matrices with INDEX/MATCH through the archived component mapping (final_component_mapping.csv next to the run's detailed_results JSON); ground-truth components without a match are dropped. Configurations without an archived mapping are N/A.
A7: Each table sheet: summary rows 6–55, gold/silver ranking rows 59–68, one block per configuration from row 72 (the 'block row' column points to it). Sheet Summary stacks all six tables. Editing a pasted matrix or the ground truth recalculates everything except the pasted eigenvalues.

Sheet Ground truth
A1: CubeSat ground truth (6 components, 20 ones, symmetric) — author-confirmed
B2: Spacecraft | C2: Guidance, Navigation, and Control (GNC) Subsystem | D2: Propulsion Subsystem | E2: Power Subsystem | F2: Reaction Wheel | G2: GNC Software | I2: eig (numpy, real) | J2: eig sorted desc | K2: det(G-λI)
A3: Spacecraft | B3: 1 | C3: 1 | D3: 1 | E3: 1 | F3: 1 | G3: 1 | I3: 3.8136065 | J3: =LARGE($I$3:$I$8,1) | K3: {=ROUND(MDETERM($B$3:$G$8-$J$3*MUNIT(6)),6)}
A4: Guidance, Navigation, and Control (GNC) Subsystem | B4: 1 | C4: 1 | D4: 0 | E4: 0 | F4: 1 | G4: 1 | I4: 1.5293166 | J4: =LARGE($I$3:$I$8,2) | K4: {=ROUND(MDETERM($B$3:$G$8-$J$4*MUNIT(6)),6)}
A5: Propulsion Subsystem | B5: 1 | C5: 0 | D5: 1 | E5: 0 | F5: 0 | G5: 0 | I5: -1 | J5: =LARGE($I$3:$I$8,3) | K5: {=ROUND(MDETERM($B$3:$G$8-$J$5*MUNIT(6)),6)}
A6: Power Subsystem | B6: 1 | C6: 0 | D6: 0 | E6: 1 | F6: 0 | G6: 0 | I6: -0.34292308 | J6: =LARGE($I$3:$I$8,4) | K6: {=ROUND(MDETERM($B$3:$G$8-$J$6*MUNIT(6)),6)}
A7: Reaction Wheel | B7: 1 | C7: 1 | D7: 0 | E7: 0 | F7: 1 | G7: 0 | I7: 1 | J7: =LARGE($I$3:$I$8,5) | K7: {=ROUND(MDETERM($B$3:$G$8-$J$7*MUNIT(6)),6)}
A8: GNC Software | B8: 1 | C8: 1 | D8: 0 | E8: 0 | F8: 0 | G8: 1 | I8: 1 | J8: =LARGE($I$3:$I$8,6) | K8: {=ROUND(MDETERM($B$3:$G$8-$J$8*MUNIT(6)),6)}
I9: =ROUND(SUM($I$3:$I$8)-($B$3+$C$4+$D$5+$E$6+$F$7+$G$8),6) | J9: =ROUND(MDETERM($B$3:$G$8)-PRODUCT($I$3:$I$8),6) | K9: ← trace / det checks (0 = eigenvalues consistent)
A12: PS ground truth (7 components, 33 ones, symmetric) — author-confirmed
B13: Bit | C13: Transmission | D13: Motor | E13: Electrical System | F13: Battery Holder | G13: Housing | H13: External Environment | J13: eig (numpy, real) | K13: eig sorted desc | L13: det(G-λI)
A14: Bit | B14: 1 | C14: 1 | D14: 0 | E14: 0 | F14: 0 | G14: 0 | H14: 1 | J14: 4.9452252 | K14: =LARGE($J$14:$J$20,1) | L14: {=ROUND(MDETERM($B$14:$H$20-$K$14*MUNIT(7)),6)}
A15: Transmission | B15: 1 | C15: 1 | D15: 1 | E15: 0 | F15: 0 | G15: 1 | H15: 1 | J15: 2.0856374 | K15: =LARGE($J$14:$J$20,2) | L15: {=ROUND(MDETERM($B$14:$H$20-$K$15*MUNIT(7)),6)}
A16: Motor | B16: 0 | C16: 1 | D16: 1 | E16: 0 | F16: 1 | G16: 1 | H16: 0 | J16: 1.618034 | K16: =LARGE($J$14:$J$20,3) | L16: {=ROUND(MDETERM($B$14:$H$20-$K$16*MUNIT(7)),6)}
A17: Electrical System | B17: 0 | C17: 0 | D17: 0 | E17: 1 | F17: 1 | G17: 1 | H17: 1 | J17: 0.29632859 | K17: =LARGE($J$14:$J$20,4) | L17: {=ROUND(MDETERM($B$14:$H$20-$K$17*MUNIT(7)),6)}
A18: Battery Holder | B18: 0 | C18: 0 | D18: 1 | E18: 1 | F18: 1 | G18: 1 | H18: 1 | J18: -0.32719117 | K18: =LARGE($J$14:$J$20,5) | L18: {=ROUND(MDETERM($B$14:$H$20-$K$18*MUNIT(7)),6)}
A19: Housing | B19: 0 | C19: 1 | D19: 1 | E19: 1 | F19: 1 | G19: 1 | H19: 1 | J19: -0.61803399 | K19: =LARGE($J$14:$J$20,6) | L19: {=ROUND(MDETERM($B$14:$H$20-$K$19*MUNIT(7)),6)}
A20: External Environment | B20: 1 | C20: 1 | D20: 0 | E20: 1 | F20: 1 | G20: 1 | H20: 1 | J20: -1 | K20: =LARGE($J$14:$J$20,7) | L20: {=ROUND(MDETERM($B$14:$H$20-$K$20*MUNIT(7)),6)}
J21: =ROUND(SUM($J$14:$J$20)-($B$14+$C$15+$D$16+$E$17+$F$18+$G$19+$H$20),6) | K21: =ROUND(MDETERM($B$14:$H$20)-PRODUCT($J$14:$J$20),6) | L21: ← trace / det checks (0 = eigenvalues consistent)
A24: Ground-truth DSMs used for every metric (identical to logs/Process/gt_cubesat.csv and gt_powerscrewdriver.csv).

Sheet Summary
A1: Table | B1: Task | C1: Use case | D1: Kind | E1: Configuration | F1: Model | G1: n_runs | H1: unsure cells | I1: unsure % | J1: coverage | K1: Precision mean | L1: Precision std | M1: Precision avg-matrix | N1: Recall mean | O1: Recall std | P1: Recall avg-matrix | Q1: F1 mean | R1: F1 std | S1: F1 avg-matrix | T1: Accuracy mean | U1: Accuracy std | V1: Accuracy avg-matrix | W1: Edit distance mean | X1: Edit distance std | Y1: Edit distance avg-matrix | Z1: Spectral distance mean | AA1: Spectral distance std | AB1: Spectral distance avg-matrix | AC1: note | AD1: block row
A2: tab:case_i_cs_experiments | B2: i | C2: CubeSat | D2: raw | E2: ='CubeSat-i'!$A$6 | F2: ='CubeSat-i'!$B$6 | G2: ='CubeSat-i'!$C$6 | H2: ='CubeSat-i'!$D$6 | I2: ='CubeSat-i'!$E$6 | J2: ='CubeSat-i'!$F$6 | K2: ='CubeSat-i'!$G$6 | L2: ='CubeSat-i'!$H$6 | M2: ='CubeSat-i'!$I$6 | N2: ='CubeSat-i'!$J$6 | O2: ='CubeSat-i'!$K$6 | P2: ='CubeSat-i'!$L$6 | Q2: ='CubeSat-i'!$M$6 | R2: ='CubeSat-i'!$N$6 | S2: ='CubeSat-i'!$O$6 | T2: ='CubeSat-i'!$P$6 | U2: ='CubeSat-i'!$Q$6 | V2: ='CubeSat-i'!$R$6 | W2: ='CubeSat-i'!$S$6 | X2: ='CubeSat-i'!$T$6 | Y2: ='CubeSat-i'!$U$6 | Z2: ='CubeSat-i'!$V$6 | AA2: ='CubeSat-i'!$W$6 | AB2: ='CubeSat-i'!$X$6 | AC2: ='CubeSat-i'!$Y$6 | AD2: ='CubeSat-i'!$Z$6
A3: tab:case_i_cs_experiments | B3: i | C3: CubeSat | D3: raw | E3: ='CubeSat-i'!$A$7 | F3: ='CubeSat-i'!$B$7 | G3: ='CubeSat-i'!$C$7 | H3: ='CubeSat-i'!$D$7 | I3: ='CubeSat-i'!$E$7 | J3: ='CubeSat-i'!$F$7 | K3: ='CubeSat-i'!$G$7 | L3: ='CubeSat-i'!$H$7 | M3: ='CubeSat-i'!$I$7 | N3: ='CubeSat-i'!$J$7 | O3: ='CubeSat-i'!$K$7 | P3: ='CubeSat-i'!$L$7 | Q3: ='CubeSat-i'!$M$7 | R3: ='CubeSat-i'!$N$7 | S3: ='CubeSat-i'!$O$7 | T3: ='CubeSat-i'!$P$7 | U3: ='CubeSat-i'!$Q$7 | V3: ='CubeSat-i'!$R$7 | W3: ='CubeSat-i'!$S$7 | X3: ='CubeSat-i'!$T$7 | Y3: ='CubeSat-i'!$U$7 | Z3: ='CubeSat-i'!$V$7 | AA3: ='CubeSat-i'!$W$7 | AB3: ='CubeSat-i'!$X$7 | AC3: ='CubeSat-i'!$Y$7 | AD3: ='CubeSat-i'!$Z$7
A4: tab:case_i_cs_experiments | B4: i | C4: CubeSat | D4: raw | E4: ='CubeSat-i'!$A$8 | F4: ='CubeSat-i'!$B$8 | G4: ='CubeSat-i'!$C$8 | H4: ='CubeSat-i'!$D$8 | I4: ='CubeSat-i'!$E$8 | J4: ='CubeSat-i'!$F$8 | K4: ='CubeSat-i'!$G$8 | L4: ='CubeSat-i'!$H$8 | M4: ='CubeSat-i'!$I$8 | N4: ='CubeSat-i'!$J$8 | O4: ='CubeSat-i'!$K$8 | P4: ='CubeSat-i'!$L$8 | Q4: ='CubeSat-i'!$M$8 | R4: ='CubeSat-i'!$N$8 | S4: ='CubeSat-i'!$O$8 | T4: ='CubeSat-i'!$P$8 | U4: ='CubeSat-i'!$Q$8 | V4: ='CubeSat-i'!$R$8 | W4: ='CubeSat-i'!$S$8 | X4: ='CubeSat-i'!$T$8 | Y4: ='CubeSat-i'!$U$8 | Z4: ='CubeSat-i'!$V$8 | AA4: ='CubeSat-i'!$W$8 | AB4: ='CubeSat-i'!$X$8 | AC4: ='CubeSat-i'!$Y$8 | AD4: ='CubeSat-i'!$Z$8
A5: tab:case_i_cs_experiments | B5: i | C5: CubeSat | D5: raw | E5: ='CubeSat-i'!$A$9 | F5: ='CubeSat-i'!$B$9 | G5: ='CubeSat-i'!$C$9 | H5: ='CubeSat-i'!$D$9 | I5: ='CubeSat-i'!$E$9 | J5: ='CubeSat-i'!$F$9 | K5: ='CubeSat-i'!$G$9 | L5: ='CubeSat-i'!$H$9 | M5: ='CubeSat-i'!$I$9 | N5: ='CubeSat-i'!$J$9 | O5: ='CubeSat-i'!$K$9 | P5: ='CubeSat-i'!$L$9 | Q5: ='CubeSat-i'!$M$9 | R5: ='CubeSat-i'!$N$9 | S5: ='CubeSat-i'!$O$9 | T5: ='CubeSat-i'!$P$9 | U5: ='CubeSat-i'!$Q$9 | V5: ='CubeSat-i'!$R$9 | W5: ='CubeSat-i'!$S$9 | X5: ='CubeSat-i'!$T$9 | Y5: ='CubeSat-i'!$U$9 | Z5: ='CubeSat-i'!$V$9 | AA5: ='CubeSat-i'!$W$9 | AB5: ='CubeSat-i'!$X$9 | AC5: ='CubeSat-i'!$Y$9 | AD5: ='CubeSat-i'!$Z$9
A6: tab:case_i_cs_experiments | B6: i | C6: CubeSat | D6: raw | E6: ='CubeSat-i'!$A$10 | F6: ='CubeSat-i'!$B$10 | G6: ='CubeSat-i'!$C$10 | H6: ='CubeSat-i'!$D$10 | I6: ='CubeSat-i'!$E$10 | J6: ='CubeSat-i'!$F$10 | K6: ='CubeSat-i'!$G$10 | L6: ='CubeSat-i'!$H$10 | M6: ='CubeSat-i'!$I$10 | N6: ='CubeSat-i'!$J$10 | O6: ='CubeSat-i'!$K$10 | P6: ='CubeSat-i'!$L$10 | Q6: ='CubeSat-i'!$M$10 | R6: ='CubeSat-i'!$N$10 | S6: ='CubeSat-i'!$O$10 | T6: ='CubeSat-i'!$P$10 | U6: ='CubeSat-i'!$Q$10 | V6: ='CubeSat-i'!$R$10 | W6: ='CubeSat-i'!$S$10 | X6: ='CubeSat-i'!$T$10 | Y6: ='CubeSat-i'!$U$10 | Z6: ='CubeSat-i'!$V$10 | AA6: ='CubeSat-i'!$W$10 | AB6: ='CubeSat-i'!$X$10 | AC6: ='CubeSat-i'!$Y$10 | AD6: ='CubeSat-i'!$Z$10
A7: tab:case_i_cs_experiments | B7: i | C7: CubeSat | D7: raw | E7: ='CubeSat-i'!$A$11 | F7: ='CubeSat-i'!$B$11 | G7: ='CubeSat-i'!$C$11 | H7: ='CubeSat-i'!$D$11 | I7: ='CubeSat-i'!$E$11 | J7: ='CubeSat-i'!$F$11 | K7: ='CubeSat-i'!$G$11 | L7: ='CubeSat-i'!$H$11 | M7: ='CubeSat-i'!$I$11 | N7: ='CubeSat-i'!$J$11 | O7: ='CubeSat-i'!$K$11 | P7: ='CubeSat-i'!$L$11 | Q7: ='CubeSat-i'!$M$11 | R7: ='CubeSat-i'!$N$11 | S7: ='CubeSat-i'!$O$11 | T7: ='CubeSat-i'!$P$11 | U7: ='CubeSat-i'!$Q$11 | V7: ='CubeSat-i'!$R$11 | W7: ='CubeSat-i'!$S$11 | X7: ='CubeSat-i'!$T$11 | Y7: ='CubeSat-i'!$U$11 | Z7: ='CubeSat-i'!$V$11 | AA7: ='CubeSat-i'!$W$11 | AB7: ='CubeSat-i'!$X$11 | AC7: ='CubeSat-i'!$Y$11 | AD7: ='CubeSat-i'!$Z$11
A8: tab:case_i_cs_experiments | B8: i | C8: CubeSat | D8: raw | E8: ='CubeSat-i'!$A$12 | F8: ='CubeSat-i'!$B$12 | G8: ='CubeSat-i'!$C$12 | H8: ='CubeSat-i'!$D$12 | I8: ='CubeSat-i'!$E$12 | J8: ='CubeSat-i'!$F$12 | K8: ='CubeSat-i'!$G$12 | L8: ='CubeSat-i'!$H$12 | M8: ='CubeSat-i'!$I$12 | N8: ='CubeSat-i'!$J$12 | O8: ='CubeSat-i'!$K$12 | P8: ='CubeSat-i'!$L$12 | Q8: ='CubeSat-i'!$M$12 | R8: ='CubeSat-i'!$N$12 | S8: ='CubeSat-i'!$O$12 | T8: ='CubeSat-i'!$P$12 | U8: ='CubeSat-i'!$Q$12 | V8: ='CubeSat-i'!$R$12 | W8: ='CubeSat-i'!$S$12 | X8: ='CubeSat-i'!$T$12 | Y8: ='CubeSat-i'!$U$12 | Z8: ='CubeSat-i'!$V$12 | AA8: ='CubeSat-i'!$W$12 | AB8: ='CubeSat-i'!$X$12 | AC8: ='CubeSat-i'!$Y$12 | AD8: ='CubeSat-i'!$Z$12
A9: tab:case_i_cs_experiments | B9: i | C9: CubeSat | D9: raw | E9: ='CubeSat-i'!$A$13 | F9: ='CubeSat-i'!$B$13 | G9: ='CubeSat-i'!$C$13 | H9: ='CubeSat-i'!$D$13 | I9: ='CubeSat-i'!$E$13 | J9: ='CubeSat-i'!$F$13 | K9: ='CubeSat-i'!$G$13 | L9: ='CubeSat-i'!$H$13 | M9: ='CubeSat-i'!$I$13 | N9: ='CubeSat-i'!$J$13 | O9: ='CubeSat-i'!$K$13 | P9: ='CubeSat-i'!$L$13 | Q9: ='CubeSat-i'!$M$13 | R9: ='CubeSat-i'!$N$13 | S9: ='CubeSat-i'!$O$13 | T9: ='CubeSat-i'!$P$13 | U9: ='CubeSat-i'!$Q$13 | V9: ='CubeSat-i'!$R$13 | W9: ='CubeSat-i'!$S$13 | X9: ='CubeSat-i'!$T$13 | Y9: ='CubeSat-i'!$U$13 | Z9: ='CubeSat-i'!$V$13 | AA9: ='CubeSat-i'!$W$13 | AB9: ='CubeSat-i'!$X$13 | AC9: ='CubeSat-i'!$Y$13 | AD9: ='CubeSat-i'!$Z$13
A10: tab:case_i_cs_experiments | B10: i | C10: CubeSat | D10: raw | E10: ='CubeSat-i'!$A$14 | F10: ='CubeSat-i'!$B$14 | G10: ='CubeSat-i'!$C$14 | H10: ='CubeSat-i'!$D$14 | I10: ='CubeSat-i'!$E$14 | J10: ='CubeSat-i'!$F$14 | K10: ='CubeSat-i'!$G$14 | L10: ='CubeSat-i'!$H$14 | M10: ='CubeSat-i'!$I$14 | N10: ='CubeSat-i'!$J$14 | O10: ='CubeSat-i'!$K$14 | P10: ='CubeSat-i'!$L$14 | Q10: ='CubeSat-i'!$M$14 | R10: ='CubeSat-i'!$N$14 | S10: ='CubeSat-i'!$O$14 | T10: ='CubeSat-i'!$P$14 | U10: ='CubeSat-i'!$Q$14 | V10: ='CubeSat-i'!$R$14 | W10: ='CubeSat-i'!$S$14 | X10: ='CubeSat-i'!$T$14 | Y10: ='CubeSat-i'!$U$14 | Z10: ='CubeSat-i'!$V$14 | AA10: ='CubeSat-i'!$W$14 | AB10: ='CubeSat-i'!$X$14 | AC10: ='CubeSat-i'!$Y$14 | AD10: ='CubeSat-i'!$Z$14
A11: tab:case_i_cs_experiments | B11: i | C11: CubeSat | D11: raw | E11: ='CubeSat-i'!$A$15 | F11: ='CubeSat-i'!$B$15 | G11: ='CubeSat-i'!$C$15 | H11: ='CubeSat-i'!$D$15 | I11: ='CubeSat-i'!$E$15 | J11: ='CubeSat-i'!$F$15 | K11: ='CubeSat-i'!$G$15 | L11: ='CubeSat-i'!$H$15 | M11: ='CubeSat-i'!$I$15 | N11: ='CubeSat-i'!$J$15 | O11: ='CubeSat-i'!$K$15 | P11: ='CubeSat-i'!$L$15 | Q11: ='CubeSat-i'!$M$15 | R11: ='CubeSat-i'!$N$15 | S11: ='CubeSat-i'!$O$15 | T11: ='CubeSat-i'!$P$15 | U11: ='CubeSat-i'!$Q$15 | V11: ='CubeSat-i'!$R$15 | W11: ='CubeSat-i'!$S$15 | X11: ='CubeSat-i'!$T$15 | Y11: ='CubeSat-i'!$U$15 | Z11: ='CubeSat-i'!$V$15 | AA11: ='CubeSat-i'!$W$15 | AB11: ='CubeSat-i'!$X$15 | AC11: ='CubeSat-i'!$Y$15 | AD11: ='CubeSat-i'!$Z$15
A12: tab:case_i_cs_experiments | B12: i | C12: CubeSat | D12: raw | E12: ='CubeSat-i'!$A$16 | F12: ='CubeSat-i'!$B$16 | G12: ='CubeSat-i'!$C$16 | H12: ='CubeSat-i'!$D$16 | I12: ='CubeSat-i'!$E$16 | J12: ='CubeSat-i'!$F$16 | K12: ='CubeSat-i'!$G$16 | L12: ='CubeSat-i'!$H$16 | M12: ='CubeSat-i'!$I$16 | N12: ='CubeSat-i'!$J$16 | O12: ='CubeSat-i'!$K$16 | P12: ='CubeSat-i'!$L$16 | Q12: ='CubeSat-i'!$M$16 | R12: ='CubeSat-i'!$N$16 | S12: ='CubeSat-i'!$O$16 | T12: ='CubeSat-i'!$P$16 | U12: ='CubeSat-i'!$Q$16 | V12: ='CubeSat-i'!$R$16 | W12: ='CubeSat-i'!$S$16 | X12: ='CubeSat-i'!$T$16 | Y12: ='CubeSat-i'!$U$16 | Z12: ='CubeSat-i'!$V$16 | AA12: ='CubeSat-i'!$W$16 | AB12: ='CubeSat-i'!$X$16 | AC12: ='CubeSat-i'!$Y$16 | AD12: ='CubeSat-i'!$Z$16
A13: tab:case_i_cs_experiments | B13: i | C13: CubeSat | D13: raw | E13: ='CubeSat-i'!$A$17 | F13: ='CubeSat-i'!$B$17 | G13: ='CubeSat-i'!$C$17 | H13: ='CubeSat-i'!$D$17 | I13: ='CubeSat-i'!$E$17 | J13: ='CubeSat-i'!$F$17 | K13: ='CubeSat-i'!$G$17 | L13: ='CubeSat-i'!$H$17 | M13: ='CubeSat-i'!$I$17 | N13: ='CubeSat-i'!$J$17 | O13: ='CubeSat-i'!$K$17 | P13: ='CubeSat-i'!$L$17 | Q13: ='CubeSat-i'!$M$17 | R13: ='CubeSat-i'!$N$17 | S13: ='CubeSat-i'!$O$17 | T13: ='CubeSat-i'!$P$17 | U13: ='CubeSat-i'!$Q$17 | V13: ='CubeSat-i'!$R$17 | W13: ='CubeSat-i'!$S$17 | X13: ='CubeSat-i'!$T$17 | Y13: ='CubeSat-i'!$U$17 | Z13: ='CubeSat-i'!$V$17 | AA13: ='CubeSat-i'!$W$17 | AB13: ='CubeSat-i'!$X$17 | AC13: ='CubeSat-i'!$Y$17 | AD13: ='CubeSat-i'!$Z$17
A14: tab:case_i_cs_experiments | B14: i | C14: CubeSat | D14: raw | E14: ='CubeSat-i'!$A$18 | F14: ='CubeSat-i'!$B$18 | G14: ='CubeSat-i'!$C$18 | H14: ='CubeSat-i'!$D$18 | I14: ='CubeSat-i'!$E$18 | J14: ='CubeSat-i'!$F$18 | K14: ='CubeSat-i'!$G$18 | L14: ='CubeSat-i'!$H$18 | M14: ='CubeSat-i'!$I$18 | N14: ='CubeSat-i'!$J$18 | O14: ='CubeSat-i'!$K$18 | P14: ='CubeSat-i'!$L$18 | Q14: ='CubeSat-i'!$M$18 | R14: ='CubeSat-i'!$N$18 | S14: ='CubeSat-i'!$O$18 | T14: ='CubeSat-i'!$P$18 | U14: ='CubeSat-i'!$Q$18 | V14: ='CubeSat-i'!$R$18 | W14: ='CubeSat-i'!$S$18 | X14: ='CubeSat-i'!$T$18 | Y14: ='CubeSat-i'!$U$18 | Z14: ='CubeSat-i'!$V$18 | AA14: ='CubeSat-i'!$W$18 | AB14: ='CubeSat-i'!$X$18 | AC14: ='CubeSat-i'!$Y$18 | AD14: ='CubeSat-i'!$Z$18
A15: tab:case_i_cs_experiments | B15: i | C15: CubeSat | D15: raw | E15: ='CubeSat-i'!$A$19 | F15: ='CubeSat-i'!$B$19 | G15: ='CubeSat-i'!$C$19 | H15: ='CubeSat-i'!$D$19 | I15: ='CubeSat-i'!$E$19 | J15: ='CubeSat-i'!$F$19 | K15: ='CubeSat-i'!$G$19 | L15: ='CubeSat-i'!$H$19 | M15: ='CubeSat-i'!$I$19 | N15: ='CubeSat-i'!$J$19 | O15: ='CubeSat-i'!$K$19 | P15: ='CubeSat-i'!$L$19 | Q15: ='CubeSat-i'!$M$19 | R15: ='CubeSat-i'!$N$19 | S15: ='CubeSat-i'!$O$19 | T15: ='CubeSat-i'!$P$19 | U15: ='CubeSat-i'!$Q$19 | V15: ='CubeSat-i'!$R$19 | W15: ='CubeSat-i'!$S$19 | X15: ='CubeSat-i'!$T$19 | Y15: ='CubeSat-i'!$U$19 | Z15: ='CubeSat-i'!$V$19 | AA15: ='CubeSat-i'!$W$19 | AB15: ='CubeSat-i'!$X$19 | AC15: ='CubeSat-i'!$Y$19 | AD15: ='CubeSat-i'!$Z$19
A16: tab:case_i_cs_experiments | B16: i | C16: CubeSat | D16: raw | E16: ='CubeSat-i'!$A$20 | F16: ='CubeSat-i'!$B$20 | G16: ='CubeSat-i'!$C$20 | H16: ='CubeSat-i'!$D$20 | I16: ='CubeSat-i'!$E$20 | J16: ='CubeSat-i'!$F$20 | K16: ='CubeSat-i'!$G$20 | L16: ='CubeSat-i'!$H$20 | M16: ='CubeSat-i'!$I$20 | N16: ='CubeSat-i'!$J$20 | O16: ='CubeSat-i'!$K$20 | P16: ='CubeSat-i'!$L$20 | Q16: ='CubeSat-i'!$M$20 | R16: ='CubeSat-i'!$N$20 | S16: ='CubeSat-i'!$O$20 | T16: ='CubeSat-i'!$P$20 | U16: ='CubeSat-i'!$Q$20 | V16: ='CubeSat-i'!$R$20 | W16: ='CubeSat-i'!$S$20 | X16: ='CubeSat-i'!$T$20 | Y16: ='CubeSat-i'!$U$20 | Z16: ='CubeSat-i'!$V$20 | AA16: ='CubeSat-i'!$W$20 | AB16: ='CubeSat-i'!$X$20 | AC16: ='CubeSat-i'!$Y$20 | AD16: ='CubeSat-i'!$Z$20
A17: tab:case_i_cs_experiments | B17: i | C17: CubeSat | D17: raw | E17: ='CubeSat-i'!$A$21 | F17: ='CubeSat-i'!$B$21 | G17: ='CubeSat-i'!$C$21 | H17: ='CubeSat-i'!$D$21 | I17: ='CubeSat-i'!$E$21 | J17: ='CubeSat-i'!$F$21 | K17: ='CubeSat-i'!$G$21 | L17: ='CubeSat-i'!$H$21 | M17: ='CubeSat-i'!$I$21 | N17: ='CubeSat-i'!$J$21 | O17: ='CubeSat-i'!$K$21 | P17: ='CubeSat-i'!$L$21 | Q17: ='CubeSat-i'!$M$21 | R17: ='CubeSat-i'!$N$21 | S17: ='CubeSat-i'!$O$21 | T17: ='CubeSat-i'!$P$21 | U17: ='CubeSat-i'!$Q$21 | V17: ='CubeSat-i'!$R$21 | W17: ='CubeSat-i'!$S$21 | X17: ='CubeSat-i'!$T$21 | Y17: ='CubeSat-i'!$U$21 | Z17: ='CubeSat-i'!$V$21 | AA17: ='CubeSat-i'!$W$21 | AB17: ='CubeSat-i'!$X$21 | AC17: ='CubeSat-i'!$Y$21 | AD17: ='CubeSat-i'!$Z$21
A18: tab:case_i_cs_experiments | B18: i | C18: CubeSat | D18: raw | E18: ='CubeSat-i'!$A$22 | F18: ='CubeSat-i'!$B$22 | G18: ='CubeSat-i'!$C$22 | H18: ='CubeSat-i'!$D$22 | I18: ='CubeSat-i'!$E$22 | J18: ='CubeSat-i'!$F$22 | K18: ='CubeSat-i'!$G$22 | L18: ='CubeSat-i'!$H$22 | M18: ='CubeSat-i'!$I$22 | N18: ='CubeSat-i'!$J$22 | O18: ='CubeSat-i'!$K$22 | P18: ='CubeSat-i'!$L$22 | Q18: ='CubeSat-i'!$M$22 | R18: ='CubeSat-i'!$N$22 | S18: ='CubeSat-i'!$O$22 | T18: ='CubeSat-i'!$P$22 | U18: ='CubeSat-i'!$Q$22 | V18: ='CubeSat-i'!$R$22 | W18: ='CubeSat-i'!$S$22 | X18: ='CubeSat-i'!$T$22 | Y18: ='CubeSat-i'!$U$22 | Z18: ='CubeSat-i'!$V$22 | AA18: ='CubeSat-i'!$W$22 | AB18: ='CubeSat-i'!$X$22 | AC18: ='CubeSat-i'!$Y$22 | AD18: ='CubeSat-i'!$Z$22
A19: tab:case_i_cs_experiments | B19: i | C19: CubeSat | D19: raw | E19: ='CubeSat-i'!$A$23 | F19: ='CubeSat-i'!$B$23 | G19: ='CubeSat-i'!$C$23 | H19: ='CubeSat-i'!$D$23 | I19: ='CubeSat-i'!$E$23 | J19: ='CubeSat-i'!$F$23 | K19: ='CubeSat-i'!$G$23 | L19: ='CubeSat-i'!$H$23 | M19: ='CubeSat-i'!$I$23 | N19: ='CubeSat-i'!$J$23 | O19: ='CubeSat-i'!$K$23 | P19: ='CubeSat-i'!$L$23 | Q19: ='CubeSat-i'!$M$23 | R19: ='CubeSat-i'!$N$23 | S19: ='CubeSat-i'!$O$23 | T19: ='CubeSat-i'!$P$23 | U19: ='CubeSat-i'!$Q$23 | V19: ='CubeSat-i'!$R$23 | W19: ='CubeSat-i'!$S$23 | X19: ='CubeSat-i'!$T$23 | Y19: ='CubeSat-i'!$U$23 | Z19: ='CubeSat-i'!$V$23 | AA19: ='CubeSat-i'!$W$23 | AB19: ='CubeSat-i'!$X$23 | AC19: ='CubeSat-i'!$Y$23 | AD19: ='CubeSat-i'!$Z$23
A20: tab:case_i_cs_experiments | B20: i | C20: CubeSat | D20: raw | E20: ='CubeSat-i'!$A$24 | F20: ='CubeSat-i'!$B$24 | G20: ='CubeSat-i'!$C$24 | H20: ='CubeSat-i'!$D$24 | I20: ='CubeSat-i'!$E$24 | J20: ='CubeSat-i'!$F$24 | K20: ='CubeSat-i'!$G$24 | L20: ='CubeSat-i'!$H$24 | M20: ='CubeSat-i'!$I$24 | N20: ='CubeSat-i'!$J$24 | O20: ='CubeSat-i'!$K$24 | P20: ='CubeSat-i'!$L$24 | Q20: ='CubeSat-i'!$M$24 | R20: ='CubeSat-i'!$N$24 | S20: ='CubeSat-i'!$O$24 | T20: ='CubeSat-i'!$P$24 | U20: ='CubeSat-i'!$Q$24 | V20: ='CubeSat-i'!$R$24 | W20: ='CubeSat-i'!$S$24 | X20: ='CubeSat-i'!$T$24 | Y20: ='CubeSat-i'!$U$24 | Z20: ='CubeSat-i'!$V$24 | AA20: ='CubeSat-i'!$W$24 | AB20: ='CubeSat-i'!$X$24 | AC20: ='CubeSat-i'!$Y$24 | AD20: ='CubeSat-i'!$Z$24
A21: tab:case_i_cs_experiments | B21: i | C21: CubeSat | D21: raw | E21: ='CubeSat-i'!$A$25 | F21: ='CubeSat-i'!$B$25 | G21: ='CubeSat-i'!$C$25 | H21: ='CubeSat-i'!$D$25 | I21: ='CubeSat-i'!$E$25 | J21: ='CubeSat-i'!$F$25 | K21: ='CubeSat-i'!$G$25 | L21: ='CubeSat-i'!$H$25 | M21: ='CubeSat-i'!$I$25 | N21: ='CubeSat-i'!$J$25 | O21: ='CubeSat-i'!$K$25 | P21: ='CubeSat-i'!$L$25 | Q21: ='CubeSat-i'!$M$25 | R21: ='CubeSat-i'!$N$25 | S21: ='CubeSat-i'!$O$25 | T21: ='CubeSat-i'!$P$25 | U21: ='CubeSat-i'!$Q$25 | V21: ='CubeSat-i'!$R$25 | W21: ='CubeSat-i'!$S$25 | X21: ='CubeSat-i'!$T$25 | Y21: ='CubeSat-i'!$U$25 | Z21: ='CubeSat-i'!$V$25 | AA21: ='CubeSat-i'!$W$25 | AB21: ='CubeSat-i'!$X$25 | AC21: ='CubeSat-i'!$Y$25 | AD21: ='CubeSat-i'!$Z$25
A22: tab:case_i_cs_experiments | B22: i | C22: CubeSat | D22: raw | E22: ='CubeSat-i'!$A$26 | F22: ='CubeSat-i'!$B$26 | G22: ='CubeSat-i'!$C$26 | H22: ='CubeSat-i'!$D$26 | I22: ='CubeSat-i'!$E$26 | J22: ='CubeSat-i'!$F$26 | K22: ='CubeSat-i'!$G$26 | L22: ='CubeSat-i'!$H$26 | M22: ='CubeSat-i'!$I$26 | N22: ='CubeSat-i'!$J$26 | O22: ='CubeSat-i'!$K$26 | P22: ='CubeSat-i'!$L$26 | Q22: ='CubeSat-i'!$M$26 | R22: ='CubeSat-i'!$N$26 | S22: ='CubeSat-i'!$O$26 | T22: ='CubeSat-i'!$P$26 | U22: ='CubeSat-i'!$Q$26 | V22: ='CubeSat-i'!$R$26 | W22: ='CubeSat-i'!$S$26 | X22: ='CubeSat-i'!$T$26 | Y22: ='CubeSat-i'!$U$26 | Z22: ='CubeSat-i'!$V$26 | AA22: ='CubeSat-i'!$W$26 | AB22: ='CubeSat-i'!$X$26 | AC22: ='CubeSat-i'!$Y$26 | AD22: ='CubeSat-i'!$Z$26
A23: tab:case_i_cs_experiments | B23: i | C23: CubeSat | D23: raw | E23: ='CubeSat-i'!$A$27 | F23: ='CubeSat-i'!$B$27 | G23: ='CubeSat-i'!$C$27 | H23: ='CubeSat-i'!$D$27 | I23: ='CubeSat-i'!$E$27 | J23: ='CubeSat-i'!$F$27 | K23: ='CubeSat-i'!$G$27 | L23: ='CubeSat-i'!$H$27 | M23: ='CubeSat-i'!$I$27 | N23: ='CubeSat-i'!$J$27 | O23: ='CubeSat-i'!$K$27 | P23: ='CubeSat-i'!$L$27 | Q23: ='CubeSat-i'!$M$27 | R23: ='CubeSat-i'!$N$27 | S23: ='CubeSat-i'!$O$27 | T23: ='CubeSat-i'!$P$27 | U23: ='CubeSat-i'!$Q$27 | V23: ='CubeSat-i'!$R$27 | W23: ='CubeSat-i'!$S$27 | X23: ='CubeSat-i'!$T$27 | Y23: ='CubeSat-i'!$U$27 | Z23: ='CubeSat-i'!$V$27 | AA23: ='CubeSat-i'!$W$27 | AB23: ='CubeSat-i'!$X$27 | AC23: ='CubeSat-i'!$Y$27 | AD23: ='CubeSat-i'!$Z$27
A24: tab:case_i_cs_experiments | B24: i | C24: CubeSat | D24: raw | E24: ='CubeSat-i'!$A$28 | F24: ='CubeSat-i'!$B$28 | G24: ='CubeSat-i'!$C$28 | H24: ='CubeSat-i'!$D$28 | I24: ='CubeSat-i'!$E$28 | J24: ='CubeSat-i'!$F$28 | K24: ='CubeSat-i'!$G$28 | L24: ='CubeSat-i'!$H$28 | M24: ='CubeSat-i'!$I$28 | N24: ='CubeSat-i'!$J$28 | O24: ='CubeSat-i'!$K$28 | P24: ='CubeSat-i'!$L$28 | Q24: ='CubeSat-i'!$M$28 | R24: ='CubeSat-i'!$N$28 | S24: ='CubeSat-i'!$O$28 | T24: ='CubeSat-i'!$P$28 | U24: ='CubeSat-i'!$Q$28 | V24: ='CubeSat-i'!$R$28 | W24: ='CubeSat-i'!$S$28 | X24: ='CubeSat-i'!$T$28 | Y24: ='CubeSat-i'!$U$28 | Z24: ='CubeSat-i'!$V$28 | AA24: ='CubeSat-i'!$W$28 | AB24: ='CubeSat-i'!$X$28 | AC24: ='CubeSat-i'!$Y$28 | AD24: ='CubeSat-i'!$Z$28
A25: tab:case_i_cs_experiments | B25: i | C25: CubeSat | D25: raw | E25: ='CubeSat-i'!$A$29 | F25: ='CubeSat-i'!$B$29 | G25: ='CubeSat-i'!$C$29 | H25: ='CubeSat-i'!$D$29 | I25: ='CubeSat-i'!$E$29 | J25: ='CubeSat-i'!$F$29 | K25: ='CubeSat-i'!$G$29 | L25: ='CubeSat-i'!$H$29 | M25: ='CubeSat-i'!$I$29 | N25: ='CubeSat-i'!$J$29 | O25: ='CubeSat-i'!$K$29 | P25: ='CubeSat-i'!$L$29 | Q25: ='CubeSat-i'!$M$29 | R25: ='CubeSat-i'!$N$29 | S25: ='CubeSat-i'!$O$29 | T25: ='CubeSat-i'!$P$29 | U25: ='CubeSat-i'!$Q$29 | V25: ='CubeSat-i'!$R$29 | W25: ='CubeSat-i'!$S$29 | X25: ='CubeSat-i'!$T$29 | Y25: ='CubeSat-i'!$U$29 | Z25: ='CubeSat-i'!$V$29 | AA25: ='CubeSat-i'!$W$29 | AB25: ='CubeSat-i'!$X$29 | AC25: ='CubeSat-i'!$Y$29 | AD25: ='CubeSat-i'!$Z$29
A26: tab:case_i_cs_experiments | B26: i | C26: CubeSat | D26: raw | E26: ='CubeSat-i'!$A$30 | F26: ='CubeSat-i'!$B$30 | G26: ='CubeSat-i'!$C$30 | H26: ='CubeSat-i'!$D$30 | I26: ='CubeSat-i'!$E$30 | J26: ='CubeSat-i'!$F$30 | K26: ='CubeSat-i'!$G$30 | L26: ='CubeSat-i'!$H$30 | M26: ='CubeSat-i'!$I$30 | N26: ='CubeSat-i'!$J$30 | O26: ='CubeSat-i'!$K$30 | P26: ='CubeSat-i'!$L$30 | Q26: ='CubeSat-i'!$M$30 | R26: ='CubeSat-i'!$N$30 | S26: ='CubeSat-i'!$O$30 | T26: ='CubeSat-i'!$P$30 | U26: ='CubeSat-i'!$Q$30 | V26: ='CubeSat-i'!$R$30 | W26: ='CubeSat-i'!$S$30 | X26: ='CubeSat-i'!$T$30 | Y26: ='CubeSat-i'!$U$30 | Z26: ='CubeSat-i'!$V$30 | AA26: ='CubeSat-i'!$W$30 | AB26: ='CubeSat-i'!$X$30 | AC26: ='CubeSat-i'!$Y$30 | AD26: ='CubeSat-i'!$Z$30
A27: tab:case_i_cs_experiments | B27: i | C27: CubeSat | D27: raw | E27: ='CubeSat-i'!$A$31 | F27: ='CubeSat-i'!$B$31 | G27: ='CubeSat-i'!$C$31 | H27: ='CubeSat-i'!$D$31 | I27: ='CubeSat-i'!$E$31 | J27: ='CubeSat-i'!$F$31 | K27: ='CubeSat-i'!$G$31 | L27: ='CubeSat-i'!$H$31 | M27: ='CubeSat-i'!$I$31 | N27: ='CubeSat-i'!$J$31 | O27: ='CubeSat-i'!$K$31 | P27: ='CubeSat-i'!$L$31 | Q27: ='CubeSat-i'!$M$31 | R27: ='CubeSat-i'!$N$31 | S27: ='CubeSat-i'!$O$31 | T27: ='CubeSat-i'!$P$31 | U27: ='CubeSat-i'!$Q$31 | V27: ='CubeSat-i'!$R$31 | W27: ='CubeSat-i'!$S$31 | X27: ='CubeSat-i'!$T$31 | Y27: ='CubeSat-i'!$U$31 | Z27: ='CubeSat-i'!$V$31 | AA27: ='CubeSat-i'!$W$31 | AB27: ='CubeSat-i'!$X$31 | AC27: ='CubeSat-i'!$Y$31 | AD27: ='CubeSat-i'!$Z$31
A28: tab:case_i_cs_experiments | B28: i | C28: CubeSat | D28: raw | E28: ='CubeSat-i'!$A$32 | F28: ='CubeSat-i'!$B$32 | G28: ='CubeSat-i'!$C$32 | H28: ='CubeSat-i'!$D$32 | I28: ='CubeSat-i'!$E$32 | J28: ='CubeSat-i'!$F$32 | K28: ='CubeSat-i'!$G$32 | L28: ='CubeSat-i'!$H$32 | M28: ='CubeSat-i'!$I$32 | N28: ='CubeSat-i'!$J$32 | O28: ='CubeSat-i'!$K$32 | P28: ='CubeSat-i'!$L$32 | Q28: ='CubeSat-i'!$M$32 | R28: ='CubeSat-i'!$N$32 | S28: ='CubeSat-i'!$O$32 | T28: ='CubeSat-i'!$P$32 | U28: ='CubeSat-i'!$Q$32 | V28: ='CubeSat-i'!$R$32 | W28: ='CubeSat-i'!$S$32 | X28: ='CubeSat-i'!$T$32 | Y28: ='CubeSat-i'!$U$32 | Z28: ='CubeSat-i'!$V$32 | AA28: ='CubeSat-i'!$W$32 | AB28: ='CubeSat-i'!$X$32 | AC28: ='CubeSat-i'!$Y$32 | AD28: ='CubeSat-i'!$Z$32
A29: tab:case_i_cs_experiments | B29: i | C29: CubeSat | D29: raw | E29: ='CubeSat-i'!$A$33 | F29: ='CubeSat-i'!$B$33 | G29: ='CubeSat-i'!$C$33 | H29: ='CubeSat-i'!$D$33 | I29: ='CubeSat-i'!$E$33 | J29: ='CubeSat-i'!$F$33 | K29: ='CubeSat-i'!$G$33 | L29: ='CubeSat-i'!$H$33 | M29: ='CubeSat-i'!$I$33 | N29: ='CubeSat-i'!$J$33 | O29: ='CubeSat-i'!$K$33 | P29: ='CubeSat-i'!$L$33 | Q29: ='CubeSat-i'!$M$33 | R29: ='CubeSat-i'!$N$33 | S29: ='CubeSat-i'!$O$33 | T29: ='CubeSat-i'!$P$33 | U29: ='CubeSat-i'!$Q$33 | V29: ='CubeSat-i'!$R$33 | W29: ='CubeSat-i'!$S$33 | X29: ='CubeSat-i'!$T$33 | Y29: ='CubeSat-i'!$U$33 | Z29: ='CubeSat-i'!$V$33 | AA29: ='CubeSat-i'!$W$33 | AB29: ='CubeSat-i'!$X$33 | AC29: ='CubeSat-i'!$Y$33 | AD29: ='CubeSat-i'!$Z$33
A30: tab:case_i_cs_experiments | B30: i | C30: CubeSat | D30: raw | E30: ='CubeSat-i'!$A$34 | F30: ='CubeSat-i'!$B$34 | G30: ='CubeSat-i'!$C$34 | H30: ='CubeSat-i'!$D$34 | I30: ='CubeSat-i'!$E$34 | J30: ='CubeSat-i'!$F$34 | K30: ='CubeSat-i'!$G$34 | L30: ='CubeSat-i'!$H$34 | M30: ='CubeSat-i'!$I$34 | N30: ='CubeSat-i'!$J$34 | O30: ='CubeSat-i'!$K$34 | P30: ='CubeSat-i'!$L$34 | Q30: ='CubeSat-i'!$M$34 | R30: ='CubeSat-i'!$N$34 | S30: ='CubeSat-i'!$O$34 | T30: ='CubeSat-i'!$P$34 | U30: ='CubeSat-i'!$Q$34 | V30: ='CubeSat-i'!$R$34 | W30: ='CubeSat-i'!$S$34 | X30: ='CubeSat-i'!$T$34 | Y30: ='CubeSat-i'!$U$34 | Z30: ='CubeSat-i'!$V$34 | AA30: ='CubeSat-i'!$W$34 | AB30: ='CubeSat-i'!$X$34 | AC30: ='CubeSat-i'!$Y$34 | AD30: ='CubeSat-i'!$Z$34
A31: tab:case_i_cs_experiments | B31: i | C31: CubeSat | D31: raw | E31: ='CubeSat-i'!$A$35 | F31: ='CubeSat-i'!$B$35 | G31: ='CubeSat-i'!$C$35 | H31: ='CubeSat-i'!$D$35 | I31: ='CubeSat-i'!$E$35 | J31: ='CubeSat-i'!$F$35 | K31: ='CubeSat-i'!$G$35 | L31: ='CubeSat-i'!$H$35 | M31: ='CubeSat-i'!$I$35 | N31: ='CubeSat-i'!$J$35 | O31: ='CubeSat-i'!$K$35 | P31: ='CubeSat-i'!$L$35 | Q31: ='CubeSat-i'!$M$35 | R31: ='CubeSat-i'!$N$35 | S31: ='CubeSat-i'!$O$35 | T31: ='CubeSat-i'!$P$35 | U31: ='CubeSat-i'!$Q$35 | V31: ='CubeSat-i'!$R$35 | W31: ='CubeSat-i'!$S$35 | X31: ='CubeSat-i'!$T$35 | Y31: ='CubeSat-i'!$U$35 | Z31: ='CubeSat-i'!$V$35 | AA31: ='CubeSat-i'!$W$35 | AB31: ='CubeSat-i'!$X$35 | AC31: ='CubeSat-i'!$Y$35 | AD31: ='CubeSat-i'!$Z$35
A32: tab:case_i_cs_experiments | B32: i | C32: CubeSat | D32: raw | E32: ='CubeSat-i'!$A$36 | F32: ='CubeSat-i'!$B$36 | G32: ='CubeSat-i'!$C$36 | H32: ='CubeSat-i'!$D$36 | I32: ='CubeSat-i'!$E$36 | J32: ='CubeSat-i'!$F$36 | K32: ='CubeSat-i'!$G$36 | L32: ='CubeSat-i'!$H$36 | M32: ='CubeSat-i'!$I$36 | N32: ='CubeSat-i'!$J$36 | O32: ='CubeSat-i'!$K$36 | P32: ='CubeSat-i'!$L$36 | Q32: ='CubeSat-i'!$M$36 | R32: ='CubeSat-i'!$N$36 | S32: ='CubeSat-i'!$O$36 | T32: ='CubeSat-i'!$P$36 | U32: ='CubeSat-i'!$Q$36 | V32: ='CubeSat-i'!$R$36 | W32: ='CubeSat-i'!$S$36 | X32: ='CubeSat-i'!$T$36 | Y32: ='CubeSat-i'!$U$36 | Z32: ='CubeSat-i'!$V$36 | AA32: ='CubeSat-i'!$W$36 | AB32: ='CubeSat-i'!$X$36 | AC32: ='CubeSat-i'!$Y$36 | AD32: ='CubeSat-i'!$Z$36
A33: tab:case_i_cs_experiments | B33: i | C33: CubeSat | D33: raw | E33: ='CubeSat-i'!$A$37 | F33: ='CubeSat-i'!$B$37 | G33: ='CubeSat-i'!$C$37 | H33: ='CubeSat-i'!$D$37 | I33: ='CubeSat-i'!$E$37 | J33: ='CubeSat-i'!$F$37 | K33: ='CubeSat-i'!$G$37 | L33: ='CubeSat-i'!$H$37 | M33: ='CubeSat-i'!$I$37 | N33: ='CubeSat-i'!$J$37 | O33: ='CubeSat-i'!$K$37 | P33: ='CubeSat-i'!$L$37 | Q33: ='CubeSat-i'!$M$37 | R33: ='CubeSat-i'!$N$37 | S33: ='CubeSat-i'!$O$37 | T33: ='CubeSat-i'!$P$37 | U33: ='CubeSat-i'!$Q$37 | V33: ='CubeSat-i'!$R$37 | W33: ='CubeSat-i'!$S$37 | X33: ='CubeSat-i'!$T$37 | Y33: ='CubeSat-i'!$U$37 | Z33: ='CubeSat-i'!$V$37 | AA33: ='CubeSat-i'!$W$37 | AB33: ='CubeSat-i'!$X$37 | AC33: ='CubeSat-i'!$Y$37 | AD33: ='CubeSat-i'!$Z$37
A34: tab:case_i_cs_experiments | B34: i | C34: CubeSat | D34: raw | E34: ='CubeSat-i'!$A$38 | F34: ='CubeSat-i'!$B$38 | G34: ='CubeSat-i'!$C$38 | H34: ='CubeSat-i'!$D$38 | I34: ='CubeSat-i'!$E$38 | J34: ='CubeSat-i'!$F$38 | K34: ='CubeSat-i'!$G$38 | L34: ='CubeSat-i'!$H$38 | M34: ='CubeSat-i'!$I$38 | N34: ='CubeSat-i'!$J$38 | O34: ='CubeSat-i'!$K$38 | P34: ='CubeSat-i'!$L$38 | Q34: ='CubeSat-i'!$M$38 | R34: ='CubeSat-i'!$N$38 | S34: ='CubeSat-i'!$O$38 | T34: ='CubeSat-i'!$P$38 | U34: ='CubeSat-i'!$Q$38 | V34: ='CubeSat-i'!$R$38 | W34: ='CubeSat-i'!$S$38 | X34: ='CubeSat-i'!$T$38 | Y34: ='CubeSat-i'!$U$38 | Z34: ='CubeSat-i'!$V$38 | AA34: ='CubeSat-i'!$W$38 | AB34: ='CubeSat-i'!$X$38 | AC34: ='CubeSat-i'!$Y$38 | AD34: ='CubeSat-i'!$Z$38
A35: tab:case_i_cs_experiments | B35: i | C35: CubeSat | D35: raw | E35: ='CubeSat-i'!$A$39 | F35: ='CubeSat-i'!$B$39 | G35: ='CubeSat-i'!$C$39 | H35: ='CubeSat-i'!$D$39 | I35: ='CubeSat-i'!$E$39 | J35: ='CubeSat-i'!$F$39 | K35: ='CubeSat-i'!$G$39 | L35: ='CubeSat-i'!$H$39 | M35: ='CubeSat-i'!$I$39 | N35: ='CubeSat-i'!$J$39 | O35: ='CubeSat-i'!$K$39 | P35: ='CubeSat-i'!$L$39 | Q35: ='CubeSat-i'!$M$39 | R35: ='CubeSat-i'!$N$39 | S35: ='CubeSat-i'!$O$39 | T35: ='CubeSat-i'!$P$39 | U35: ='CubeSat-i'!$Q$39 | V35: ='CubeSat-i'!$R$39 | W35: ='CubeSat-i'!$S$39 | X35: ='CubeSat-i'!$T$39 | Y35: ='CubeSat-i'!$U$39 | Z35: ='CubeSat-i'!$V$39 | AA35: ='CubeSat-i'!$W$39 | AB35: ='CubeSat-i'!$X$39 | AC35: ='CubeSat-i'!$Y$39 | AD35: ='CubeSat-i'!$Z$39
A36: tab:case_i_cs_experiments | B36: i | C36: CubeSat | D36: raw | E36: ='CubeSat-i'!$A$40 | F36: ='CubeSat-i'!$B$40 | G36: ='CubeSat-i'!$C$40 | H36: ='CubeSat-i'!$D$40 | I36: ='CubeSat-i'!$E$40 | J36: ='CubeSat-i'!$F$40 | K36: ='CubeSat-i'!$G$40 | L36: ='CubeSat-i'!$H$40 | M36: ='CubeSat-i'!$I$40 | N36: ='CubeSat-i'!$J$40 | O36: ='CubeSat-i'!$K$40 | P36: ='CubeSat-i'!$L$40 | Q36: ='CubeSat-i'!$M$40 | R36: ='CubeSat-i'!$N$40 | S36: ='CubeSat-i'!$O$40 | T36: ='CubeSat-i'!$P$40 | U36: ='CubeSat-i'!$Q$40 | V36: ='CubeSat-i'!$R$40 | W36: ='CubeSat-i'!$S$40 | X36: ='CubeSat-i'!$T$40 | Y36: ='CubeSat-i'!$U$40 | Z36: ='CubeSat-i'!$V$40 | AA36: ='CubeSat-i'!$W$40 | AB36: ='CubeSat-i'!$X$40 | AC36: ='CubeSat-i'!$Y$40 | AD36: ='CubeSat-i'!$Z$40
A37: tab:case_i_cs_experiments | B37: i | C37: CubeSat | D37: raw | E37: ='CubeSat-i'!$A$41 | F37: ='CubeSat-i'!$B$41 | G37: ='CubeSat-i'!$C$41 | H37: ='CubeSat-i'!$D$41 | I37: ='CubeSat-i'!$E$41 | J37: ='CubeSat-i'!$F$41 | K37: ='CubeSat-i'!$G$41 | L37: ='CubeSat-i'!$H$41 | M37: ='CubeSat-i'!$I$41 | N37: ='CubeSat-i'!$J$41 | O37: ='CubeSat-i'!$K$41 | P37: ='CubeSat-i'!$L$41 | Q37: ='CubeSat-i'!$M$41 | R37: ='CubeSat-i'!$N$41 | S37: ='CubeSat-i'!$O$41 | T37: ='CubeSat-i'!$P$41 | U37: ='CubeSat-i'!$Q$41 | V37: ='CubeSat-i'!$R$41 | W37: ='CubeSat-i'!$S$41 | X37: ='CubeSat-i'!$T$41 | Y37: ='CubeSat-i'!$U$41 | Z37: ='CubeSat-i'!$V$41 | AA37: ='CubeSat-i'!$W$41 | AB37: ='CubeSat-i'!$X$41 | AC37: ='CubeSat-i'!$Y$41 | AD37: ='CubeSat-i'!$Z$41
A38: tab:case_i_cs_experiments | B38: i | C38: CubeSat | D38: raw | E38: ='CubeSat-i'!$A$42 | F38: ='CubeSat-i'!$B$42 | G38: ='CubeSat-i'!$C$42 | H38: ='CubeSat-i'!$D$42 | I38: ='CubeSat-i'!$E$42 | J38: ='CubeSat-i'!$F$42 | K38: ='CubeSat-i'!$G$42 | L38: ='CubeSat-i'!$H$42 | M38: ='CubeSat-i'!$I$42 | N38: ='CubeSat-i'!$J$42 | O38: ='CubeSat-i'!$K$42 | P38: ='CubeSat-i'!$L$42 | Q38: ='CubeSat-i'!$M$42 | R38: ='CubeSat-i'!$N$42 | S38: ='CubeSat-i'!$O$42 | T38: ='CubeSat-i'!$P$42 | U38: ='CubeSat-i'!$Q$42 | V38: ='CubeSat-i'!$R$42 | W38: ='CubeSat-i'!$S$42 | X38: ='CubeSat-i'!$T$42 | Y38: ='CubeSat-i'!$U$42 | Z38: ='CubeSat-i'!$V$42 | AA38: ='CubeSat-i'!$W$42 | AB38: ='CubeSat-i'!$X$42 | AC38: ='CubeSat-i'!$Y$42 | AD38: ='CubeSat-i'!$Z$42
A39: tab:case_i_cs_experiments | B39: i | C39: CubeSat | D39: raw | E39: ='CubeSat-i'!$A$43 | F39: ='CubeSat-i'!$B$43 | G39: ='CubeSat-i'!$C$43 | H39: ='CubeSat-i'!$D$43 | I39: ='CubeSat-i'!$E$43 | J39: ='CubeSat-i'!$F$43 | K39: ='CubeSat-i'!$G$43 | L39: ='CubeSat-i'!$H$43 | M39: ='CubeSat-i'!$I$43 | N39: ='CubeSat-i'!$J$43 | O39: ='CubeSat-i'!$K$43 | P39: ='CubeSat-i'!$L$43 | Q39: ='CubeSat-i'!$M$43 | R39: ='CubeSat-i'!$N$43 | S39: ='CubeSat-i'!$O$43 | T39: ='CubeSat-i'!$P$43 | U39: ='CubeSat-i'!$Q$43 | V39: ='CubeSat-i'!$R$43 | W39: ='CubeSat-i'!$S$43 | X39: ='CubeSat-i'!$T$43 | Y39: ='CubeSat-i'!$U$43 | Z39: ='CubeSat-i'!$V$43 | AA39: ='CubeSat-i'!$W$43 | AB39: ='CubeSat-i'!$X$43 | AC39: ='CubeSat-i'!$Y$43 | AD39: ='CubeSat-i'!$Z$43
A40: tab:case_i_cs_experiments | B40: i | C40: CubeSat | D40: raw | E40: ='CubeSat-i'!$A$44 | F40: ='CubeSat-i'!$B$44 | G40: ='CubeSat-i'!$C$44 | H40: ='CubeSat-i'!$D$44 | I40: ='CubeSat-i'!$E$44 | J40: ='CubeSat-i'!$F$44 | K40: ='CubeSat-i'!$G$44 | L40: ='CubeSat-i'!$H$44 | M40: ='CubeSat-i'!$I$44 | N40: ='CubeSat-i'!$J$44 | O40: ='CubeSat-i'!$K$44 | P40: ='CubeSat-i'!$L$44 | Q40: ='CubeSat-i'!$M$44 | R40: ='CubeSat-i'!$N$44 | S40: ='CubeSat-i'!$O$44 | T40: ='CubeSat-i'!$P$44 | U40: ='CubeSat-i'!$Q$44 | V40: ='CubeSat-i'!$R$44 | W40: ='CubeSat-i'!$S$44 | X40: ='CubeSat-i'!$T$44 | Y40: ='CubeSat-i'!$U$44 | Z40: ='CubeSat-i'!$V$44 | AA40: ='CubeSat-i'!$W$44 | AB40: ='CubeSat-i'!$X$44 | AC40: ='CubeSat-i'!$Y$44 | AD40: ='CubeSat-i'!$Z$44
...

Sheet CubeSat-i
A1: CubeSat-i — metrics as spreadsheet formulas over the pasted run matrices (raw matrices)
A2: Rows 6–55: summary (all formulas referencing the blocks below). Rows 59–68: gold/silver ranking. Blocks from row 72: pasted run matrices, then every metric as a formula.
A5: Configuration | B5: Model | C5: n_runs | D5: unsure cells | E5: unsure % | F5: coverage | G5: Precision mean | H5: Precision std | I5: Precision avg-matrix | J5: Recall mean | K5: Recall std | L5: Recall avg-matrix | M5: F1 mean | N5: F1 std | O5: F1 avg-matrix | P5: Accuracy mean | Q5: Accuracy std | R5: Accuracy avg-matrix | S5: Edit distance mean | T5: Edit distance std | U5: Edit distance avg-matrix | V5: Spectral distance mean | W5: Spectral distance std | X5: Spectral distance avg-matrix | Y5: note | Z5: block row
A6: LLM | B6: gpt4-turbo-preview | C6: =COUNT($B$82,$C$82,$D$82,$E$82,$F$82) | D6: =SUM($B$92:$F$92) | E6: =IFERROR(100*$D$6/($C$6*36),0) | F6: =IFERROR(1-$D$6/($C$6*36),0) | G6: =$H$86 | H6: =$I$86 | I6: =$G$86 | J6: =$H$87 | K6: =$I$87 | L6: =$G$87 | M6: =$H$88 | N6: =$I$88 | O6: =$G$88 | P6: =$H$89 | Q6: =$I$89 | R6: =$G$89 | S6: =$H$90 | T6: =$I$90 | U6: =$G$90 | V6: =$H$91 | W6: =$I$91 | X6: =$G$91 | Z6: 72
A7: LLM | B7: gpt4o | C7: =COUNT($B$130,$C$130,$D$130,$E$130,$F$130) | D7: =SUM($B$140:$F$140) | E7: =IFERROR(100*$D$7/($C$7*36),0) | F7: =IFERROR(1-$D$7/($C$7*36),0) | G7: =$H$134 | H7: =$I$134 | I7: =$G$134 | J7: =$H$135 | K7: =$I$135 | L7: =$G$135 | M7: =$H$136 | N7: =$I$136 | O7: =$G$136 | P7: =$H$137 | Q7: =$I$137 | R7: =$G$137 | S7: =$H$138 | T7: =$I$138 | U7: =$G$138 | V7: =$H$139 | W7: =$I$139 | X7: =$G$139 | Z7: 120
A8: LLM | B8: mixtral:8x22b | C8: =COUNT($B$178,$C$178,$D$178,$E$178,$F$178) | D8: =SUM($B$188:$F$188) | E8: =IFERROR(100*$D$8/($C$8*36),0) | F8: =IFERROR(1-$D$8/($C$8*36),0) | G8: =$H$182 | H8: =$I$182 | I8: =$G$182 | J8: =$H$183 | K8: =$I$183 | L8: =$G$183 | M8: =$H$184 | N8: =$I$184 | O8: =$G$184 | P8: =$H$185 | Q8: =$I$185 | R8: =$G$185 | S8: =$H$186 | T8: =$I$186 | U8: =$G$186 | V8: =$H$187 | W8: =$I$187 | X8: =$G$187 | Z8: 168
A9: LLM | B9: llama3.3:70b | C9: =COUNT($B$226,$C$226,$D$226,$E$226,$F$226) | D9: =SUM($B$236:$F$236) | E9: =IFERROR(100*$D$9/($C$9*36),0) | F9: =IFERROR(1-$D$9/($C$9*36),0) | G9: =$H$230 | H9: =$I$230 | I9: =$G$230 | J9: =$H$231 | K9: =$I$231 | L9: =$G$231 | M9: =$H$232 | N9: =$I$232 | O9: =$G$232 | P9: =$H$233 | Q9: =$I$233 | R9: =$G$233 | S9: =$H$234 | T9: =$I$234 | U9: =$G$234 | V9: =$H$235 | W9: =$I$235 | X9: =$G$235 | Z9: 216
A10: LLM | B10: deepseek-r1:14b | C10: =COUNT($B$274,$C$274,$D$274,$E$274,$F$274) | D10: =SUM($B$284:$F$284) | E10: =IFERROR(100*$D$10/($C$10*36),0) | F10: =IFERROR(1-$D$10/($C$10*36),0) | G10: =$H$278 | H10: =$I$278 | I10: =$G$278 | J10: =$H$279 | K10: =$I$279 | L10: =$G$279 | M10: =$H$280 | N10: =$I$280 | O10: =$G$280 | P10: =$H$281 | Q10: =$I$281 | R10: =$G$281 | S10: =$H$282 | T10: =$I$282 | U10: =$G$282 | V10: =$H$283 | W10: =$I$283 | X10: =$G$283 | Z10: 264
A11: RAG R1 | B11: gpt4-turbo-preview | C11: =COUNT($B$322,$C$322,$D$322,$E$322,$F$322) | D11: =SUM($B$332:$F$332) | E11: =IFERROR(100*$D$11/($C$11*36),0) | F11: =IFERROR(1-$D$11/($C$11*36),0) | G11: =$H$326 | H11: =$I$326 | I11: =$G$326 | J11: =$H$327 | K11: =$I$327 | L11: =$G$327 | M11: =$H$328 | N11: =$I$328 | O11: =$G$328 | P11: =$H$329 | Q11: =$I$329 | R11: =$G$329 | S11: =$H$330 | T11: =$I$330 | U11: =$G$330 | V11: =$H$331 | W11: =$I$331 | X11: =$G$331 | Z11: 312
A12: RAG R1 | B12: gpt4o | C12: 0 | G12: N/A | H12: N/A | I12: N/A | J12: N/A | K12: N/A | L12: N/A | M12: N/A | N12: N/A | O12: N/A | P12: N/A | Q12: N/A | R12: N/A | S12: N/A | T12: N/A | U12: N/A | V12: N/A | W12: N/A | X12: N/A | Y12: N/A
A13: RAG R1 | B13: mixtral:8x22b | C13: =COUNT($B$370,$C$370,$D$370,$E$370,$F$370) | D13: =SUM($B$380:$F$380) | E13: =IFERROR(100*$D$13/($C$13*36),0) | F13: =IFERROR(1-$D$13/($C$13*36),0) | G13: =$H$374 | H13: =$I$374 | I13: =$G$374 | J13: =$H$375 | K13: =$I$375 | L13: =$G$375 | M13: =$H$376 | N13: =$I$376 | O13: =$G$376 | P13: =$H$377 | Q13: =$I$377 | R13: =$G$377 | S13: =$H$378 | T13: =$I$378 | U13: =$G$378 | V13: =$H$379 | W13: =$I$379 | X13: =$G$379 | Z13: 360
A14: RAG R1 | B14: llama3.3:70b | C14: =COUNT($B$418,$C$418,$D$418,$E$418,$F$418) | D14: =SUM($B$428:$F$428) | E14: =IFERROR(100*$D$14/($C$14*36),0) | F14: =IFERROR(1-$D$14/($C$14*36),0) | G14: =$H$422 | H14: =$I$422 | I14: =$G$422 | J14: =$H$423 | K14: =$I$423 | L14: =$G$423 | M14: =$H$424 | N14: =$I$424 | O14: =$G$424 | P14: =$H$425 | Q14: =$I$425 | R14: =$G$425 | S14: =$H$426 | T14: =$I$426 | U14: =$G$426 | V14: =$H$427 | W14: =$I$427 | X14: =$G$427 | Z14: 408
A15: RAG R1 | B15: deepseek-r1:14b | C15: =COUNT($B$466,$C$466,$D$466,$E$466,$F$466) | D15: =SUM($B$476:$F$476) | E15: =IFERROR(100*$D$15/($C$15*36),0) | F15: =IFERROR(1-$D$15/($C$15*36),0) | G15: =$H$470 | H15: =$I$470 | I15: =$G$470 | J15: =$H$471 | K15: =$I$471 | L15: =$G$471 | M15: =$H$472 | N15: =$I$472 | O15: =$G$472 | P15: =$H$473 | Q15: =$I$473 | R15: =$G$473 | S15: =$H$474 | T15: =$I$474 | U15: =$G$474 | V15: =$H$475 | W15: =$I$475 | X15: =$G$475 | Z15: 456
A16: RAG R2 | B16: gpt4-turbo-preview | C16: =COUNT($B$514,$C$514,$D$514,$E$514,$F$514) | D16: =SUM($B$524:$F$524) | E16: =IFERROR(100*$D$16/($C$16*36),0) | F16: =IFERROR(1-$D$16/($C$16*36),0) | G16: =$H$518 | H16: =$I$518 | I16: =$G$518 | J16: =$H$519 | K16: =$I$519 | L16: =$G$519 | M16: =$H$520 | N16: =$I$520 | O16: =$G$520 | P16: =$H$521 | Q16: =$I$521 | R16: =$G$521 | S16: =$H$522 | T16: =$I$522 | U16: =$G$522 | V16: =$H$523 | W16: =$I$523 | X16: =$G$523 | Z16: 504
A17: RAG R2 | B17: gpt4o | C17: 0 | G17: N/A | H17: N/A | I17: N/A | J17: N/A | K17: N/A | L17: N/A | M17: N/A | N17: N/A | O17: N/A | P17: N/A | Q17: N/A | R17: N/A | S17: N/A | T17: N/A | U17: N/A | V17: N/A | W17: N/A | X17: N/A | Y17: N/A
A18: RAG R2 | B18: mixtral:8x22b | C18: =COUNT($B$562,$C$562,$D$562,$E$562,$F$562) | D18: =SUM($B$572:$F$572) | E18: =IFERROR(100*$D$18/($C$18*36),0) | F18: =IFERROR(1-$D$18/($C$18*36),0) | G18: =$H$566 | H18: =$I$566 | I18: =$G$566 | J18: =$H$567 | K18: =$I$567 | L18: =$G$567 | M18: =$H$568 | N18: =$I$568 | O18: =$G$568 | P18: =$H$569 | Q18: =$I$569 | R18: =$G$569 | S18: =$H$570 | T18: =$I$570 | U18: =$G$570 | V18: =$H$571 | W18: =$I$571 | X18: =$G$571 | Z18: 552
A19: RAG R2 | B19: llama3.3:70b | C19: =COUNT($B$610,$C$610,$D$610,$E$610,$F$610) | D19: =SUM($B$620:$F$620) | E19: =IFERROR(100*$D$19/($C$19*36),0) | F19: =IFERROR(1-$D$19/($C$19*36),0) | G19: =$H$614 | H19: =$I$614 | I19: =$G$614 | J19: =$H$615 | K19: =$I$615 | L19: =$G$615 | M19: =$H$616 | N19: =$I$616 | O19: =$G$616 | P19: =$H$617 | Q19: =$I$617 | R19: =$G$617 | S19: =$H$618 | T19: =$I$618 | U19: =$G$618 | V19: =$H$619 | W19: =$I$619 | X19: =$G$619 | Z19: 600
A20: RAG R2 | B20: deepseek-r1:14b | C20: =COUNT($B$658,$C$658,$D$658,$E$658,$F$658) | D20: =SUM($B$668:$F$668) | E20: =IFERROR(100*$D$20/($C$20*36),0) | F20: =IFERROR(1-$D$20/($C$20*36),0) | G20: =$H$662 | H20: =$I$662 | I20: =$G$662 | J20: =$H$663 | K20: =$I$663 | L20: =$G$663 | M20: =$H$664 | N20: =$I$664 | O20: =$G$664 | P20: =$H$665 | Q20: =$I$665 | R20: =$G$665 | S20: =$H$666 | T20: =$I$666 | U20: =$G$666 | V20: =$H$667 | W20: =$I$667 | X20: =$G$667 | Z20: 648
A21: RAG R3 | B21: gpt4-turbo-preview | C21: =COUNT($B$706,$C$706,$D$706,$E$706,$F$706) | D21: =SUM($B$716:$F$716) | E21: =IFERROR(100*$D$21/($C$21*36),0) | F21: =IFERROR(1-$D$21/($C$21*36),0) | G21: =$H$710 | H21: =$I$710 | I21: =$G$710 | J21: =$H$711 | K21: =$I$711 | L21: =$G$711 | M21: =$H$712 | N21: =$I$712 | O21: =$G$712 | P21: =$H$713 | Q21: =$I$713 | R21: =$G$713 | S21: =$H$714 | T21: =$I$714 | U21: =$G$714 | V21: =$H$715 | W21: =$I$715 | X21: =$G$715 | Z21: 696
A22: RAG R3 | B22: gpt4o | C22: 0 | G22: N/A | H22: N/A | I22: N/A | J22: N/A | K22: N/A | L22: N/A | M22: N/A | N22: N/A | O22: N/A | P22: N/A | Q22: N/A | R22: N/A | S22: N/A | T22: N/A | U22: N/A | V22: N/A | W22: N/A | X22: N/A | Y22: N/A
A23: RAG R3 | B23: mixtral:8x22b | C23: =COUNT($B$754,$C$754,$D$754,$E$754,$F$754) | D23: =SUM($B$764:$F$764) | E23: =IFERROR(100*$D$23/($C$23*36),0) | F23: =IFERROR(1-$D$23/($C$23*36),0) | G23: =$H$758 | H23: =$I$758 | I23: =$G$758 | J23: =$H$759 | K23: =$I$759 | L23: =$G$759 | M23: =$H$760 | N23: =$I$760 | O23: =$G$760 | P23: =$H$761 | Q23: =$I$761 | R23: =$G$761 | S23: =$H$762 | T23: =$I$762 | U23: =$G$762 | V23: =$H$763 | W23: =$I$763 | X23: =$G$763 | Z23: 744
A24: RAG R3 | B24: llama3.3:70b | C24: =COUNT($B$802,$C$802,$D$802,$E$802,$F$802) | D24: =SUM($B$812:$F$812) | E24: =IFERROR(100*$D$24/($C$24*36),0) | F24: =IFERROR(1-$D$24/($C$24*36),0) | G24: =$H$806 | H24: =$I$806 | I24: =$G$806 | J24: =$H$807 | K24: =$I$807 | L24: =$G$807 | M24: =$H$808 | N24: =$I$808 | O24: =$G$808 | P24: =$H$809 | Q24: =$I$809 | R24: =$G$809 | S24: =$H$810 | T24: =$I$810 | U24: =$G$810 | V24: =$H$811 | W24: =$I$811 | X24: =$G$811 | Z24: 792
A25: RAG R3 | B25: deepseek-r1:14b | C25: =COUNT($B$850,$C$850,$D$850,$E$850,$F$850) | D25: =SUM($B$860:$F$860) | E25: =IFERROR(100*$D$25/($C$25*36),0) | F25: =IFERROR(1-$D$25/($C$25*36),0) | G25: =$H$854 | H25: =$I$854 | I25: =$G$854 | J25: =$H$855 | K25: =$I$855 | L25: =$G$855 | M25: =$H$856 | N25: =$I$856 | O25: =$G$856 | P25: =$H$857 | Q25: =$I$857 | R25: =$G$857 | S25: =$H$858 | T25: =$I$858 | U25: =$G$858 | V25: =$H$859 | W25: =$I$859 | X25: =$G$859 | Z25: 840
A26: RAG R1-R2 | B26: gpt4-turbo-preview | C26: =COUNT($B$898,$C$898,$D$898,$E$898,$F$898) | D26: =SUM($B$908:$F$908) | E26: =IFERROR(100*$D$26/($C$26*36),0) | F26: =IFERROR(1-$D$26/($C$26*36),0) | G26: =$H$902 | H26: =$I$902 | I26: =$G$902 | J26: =$H$903 | K26: =$I$903 | L26: =$G$903 | M26: =$H$904 | N26: =$I$904 | O26: =$G$904 | P26: =$H$905 | Q26: =$I$905 | R26: =$G$905 | S26: =$H$906 | T26: =$I$906 | U26: =$G$906 | V26: =$H$907 | W26: =$I$907 | X26: =$G$907 | Z26: 888
A27: RAG R1-R2 | B27: gpt4o | C27: 0 | G27: N/A | H27: N/A | I27: N/A | J27: N/A | K27: N/A | L27: N/A | M27: N/A | N27: N/A | O27: N/A | P27: N/A | Q27: N/A | R27: N/A | S27: N/A | T27: N/A | U27: N/A | V27: N/A | W27: N/A | X27: N/A | Y27: N/A
A28: RAG R1-R2 | B28: mixtral:8x22b | C28: =COUNT($B$946,$C$946,$D$946,$E$946,$F$946) | D28: =SUM($B$956:$F$956) | E28: =IFERROR(100*$D$28/($C$28*36),0) | F28: =IFERROR(1-$D$28/($C$28*36),0) | G28: =$H$950 | H28: =$I$950 | I28: =$G$950 | J28: =$H$951 | K28: =$I$951 | L28: =$G$951 | M28: =$H$952 | N28: =$I$952 | O28: =$G$952 | P28: =$H$953 | Q28: =$I$953 | R28: =$G$953 | S28: =$H$954 | T28: =$I$954 | U28: =$G$954 | V28: =$H$955 | W28: =$I$955 | X28: =$G$955 | Z28: 936
A29: RAG R1-R2 | B29: llama3.3:70b | C29: =COUNT($B$994,$C$994,$D$994,$E$994,$F$994) | D29: =SUM($B$1004:$F$1004) | E29: =IFERROR(100*$D$29/($C$29*36),0) | F29: =IFERROR(1-$D$29/($C$29*36),0) | G29: =$H$998 | H29: =$I$998 | I29: =$G$998 | J29: =$H$999 | K29: =$I$999 | L29: =$G$999 | M29: =$H$1000 | N29: =$I$1000 | O29: =$G$1000 | P29: =$H$1001 | Q29: =$I$1001 | R29: =$G$1001 | S29: =$H$1002 | T29: =$I$1002 | U29: =$G$1002 | V29: =$H$1003 | W29: =$I$1003 | X29: =$G$1003 | Z29: 984
A30: RAG R1-R2 | B30: deepseek-r1:14b | C30: =COUNT($B$1042,$C$1042,$D$1042,$E$1042,$F$1042) | D30: =SUM($B$1052:$F$1052) | E30: =IFERROR(100*$D$30/($C$30*36),0) | F30: =IFERROR(1-$D$30/($C$30*36),0) | G30: =$H$1046 | H30: =$I$1046 | I30: =$G$1046 | J30: =$H$1047 | K30: =$I$1047 | L30: =$G$1047 | M30: =$H$1048 | N30: =$I$1048 | O30: =$G$1048 | P30: =$H$1049 | Q30: =$I$1049 | R30: =$G$1049 | S30: =$H$1050 | T30: =$I$1050 | U30: =$G$1050 | V30: =$H$1051 | W30: =$I$1051 | X30: =$G$1051 | Z30: 1032
A31: RAG R1-R3 | B31: gpt4-turbo-preview | C31: =COUNT($B$1090,$C$1090,$D$1090,$E$1090,$F$1090) | D31: =SUM($B$1100:$F$1100) | E31: =IFERROR(100*$D$31/($C$31*36),0) | F31: =IFERROR(1-$D$31/($C$31*36),0) | G31: =$H$1094 | H31: =$I$1094 | I31: =$G$1094 | J31: =$H$1095 | K31: =$I$1095 | L31: =$G$1095 | M31: =$H$1096 | N31: =$I$1096 | O31: =$G$1096 | P31: =$H$1097 | Q31: =$I$1097 | R31: =$G$1097 | S31: =$H$1098 | T31: =$I$1098 | U31: =$G$1098 | V31: =$H$1099 | W31: =$I$1099 | X31: =$G$1099 | Z31: 1080
A32: RAG R1-R3 | B32: gpt4o | C32: 0 | G32: N/A | H32: N/A | I32: N/A | J32: N/A | K32: N/A | L32: N/A | M32: N/A | N32: N/A | O32: N/A | P32: N/A | Q32: N/A | R32: N/A | S32: N/A | T32: N/A | U32: N/A | V32: N/A | W32: N/A | X32: N/A | Y32: N/A
A33: RAG R1-R3 | B33: mixtral:8x22b | C33: =COUNT($B$1138,$C$1138,$D$1138,$E$1138,$F$1138) | D33: =SUM($B$1148:$F$1148) | E33: =IFERROR(100*$D$33/($C$33*36),0) | F33: =IFERROR(1-$D$33/($C$33*36),0) | G33: =$H$1142 | H33: =$I$1142 | I33: =$G$1142 | J33: =$H$1143 | K33: =$I$1143 | L33: =$G$1143 | M33: =$H$1144 | N33: =$I$1144 | O33: =$G$1144 | P33: =$H$1145 | Q33: =$I$1145 | R33: =$G$1145 | S33: =$H$1146 | T33: =$I$1146 | U33: =$G$1146 | V33: =$H$1147 | W33: =$I$1147 | X33: =$G$1147 | Z33: 1128
A34: RAG R1-R3 | B34: llama3.3:70b | C34: =COUNT($B$1186,$C$1186,$D$1186,$E$1186,$F$1186) | D34: =SUM($B$1196:$F$1196) | E34: =IFERROR(100*$D$34/($C$34*36),0) | F34: =IFERROR(1-$D$34/($C$34*36),0) | G34: =$H$1190 | H34: =$I$1190 | I34: =$G$1190 | J34: =$H$1191 | K34: =$I$1191 | L34: =$G$1191 | M34: =$H$1192 | N34: =$I$1192 | O34: =$G$1192 | P34: =$H$1193 | Q34: =$I$1193 | R34: =$G$1193 | S34: =$H$1194 | T34: =$I$1194 | U34: =$G$1194 | V34: =$H$1195 | W34: =$I$1195 | X34: =$G$1195 | Z34: 1176
A35: RAG R1-R3 | B35: deepseek-r1:14b | C35: =COUNT($B$1234,$C$1234,$D$1234,$E$1234,$F$1234) | D35: =SUM($B$1244:$F$1244) | E35: =IFERROR(100*$D$35/($C$35*36),0) | F35: =IFERROR(1-$D$35/($C$35*36),0) | G35: =$H$1238 | H35: =$I$1238 | I35: =$G$1238 | J35: =$H$1239 | K35: =$I$1239 | L35: =$G$1239 | M35: =$H$1240 | N35: =$I$1240 | O35: =$G$1240 | P35: =$H$1241 | Q35: =$I$1241 | R35: =$G$1241 | S35: =$H$1242 | T35: =$I$1242 | U35: =$G$1242 | V35: =$H$1243 | W35: =$I$1243 | X35: =$G$1243 | Z35: 1224
A36: RAG R2-R3 | B36: gpt4-turbo-preview | C36: =COUNT($B$1282,$C$1282,$D$1282,$E$1282,$F$1282) | D36: =SUM($B$1292:$F$1292) | E36: =IFERROR(100*$D$36/($C$36*36),0) | F36: =IFERROR(1-$D$36/($C$36*36),0) | G36: =$H$1286 | H36: =$I$1286 | I36: =$G$1286 | J36: =$H$1287 | K36: =$I$1287 | L36: =$G$1287 | M36: =$H$1288 | N36: =$I$1288 | O36: =$G$1288 | P36: =$H$1289 | Q36: =$I$1289 | R36: =$G$1289 | S36: =$H$1290 | T36: =$I$1290 | U36: =$G$1290 | V36: =$H$1291 | W36: =$I$1291 | X36: =$G$1291 | Z36: 1272
A37: RAG R2-R3 | B37: gpt4o | C37: 0 | G37: N/A | H37: N/A | I37: N/A | J37: N/A | K37: N/A | L37: N/A | M37: N/A | N37: N/A | O37: N/A | P37: N/A | Q37: N/A | R37: N/A | S37: N/A | T37: N/A | U37: N/A | V37: N/A | W37: N/A | X37: N/A | Y37: N/A
A38: RAG R2-R3 | B38: mixtral:8x22b | C38: =COUNT($B$1330,$C$1330,$D$1330,$E$1330,$F$1330) | D38: =SUM($B$1340:$F$1340) | E38: =IFERROR(100*$D$38/($C$38*36),0) | F38: =IFERROR(1-$D$38/($C$38*36),0) | G38: =$H$1334 | H38: =$I$1334 | I38: =$G$1334 | J38: =$H$1335 | K38: =$I$1335 | L38: =$G$1335 | M38: =$H$1336 | N38: =$I$1336 | O38: =$G$1336 | P38: =$H$1337 | Q38: =$I$1337 | R38: =$G$1337 | S38: =$H$1338 | T38: =$I$1338 | U38: =$G$1338 | V38: =$H$1339 | W38: =$I$1339 | X38: =$G$1339 | Z38: 1320
A39: RAG R2-R3 | B39: llama3.3:70b | C39: =COUNT($B$1378,$C$1378,$D$1378,$E$1378,$F$1378) | D39: =SUM($B$1388:$F$1388) | E39: =IFERROR(100*$D$39/($C$39*36),0) | F39: =IFERROR(1-$D$39/($C$39*36),0) | G39: =$H$1382 | H39: =$I$1382 | I39: =$G$1382 | J39: =$H$1383 | K39: =$I$1383 | L39: =$G$1383 | M39: =$H$1384 | N39: =$I$1384 | O39: =$G$1384 | P39: =$H$1385 | Q39: =$I$1385 | R39: =$G$1385 | S39: =$H$1386 | T39: =$I$1386 | U39: =$G$1386 | V39: =$H$1387 | W39: =$I$1387 | X39: =$G$1387 | Z39: 1368
A40: RAG R2-R3 | B40: deepseek-r1:14b | C40: =COUNT($B$1426,$C$1426,$D$1426,$E$1426,$F$1426) | D40: =SUM($B$1436:$F$1436) | E40: =IFERROR(100*$D$40/($C$40*36),0) | F40: =IFERROR(1-$D$40/($C$40*36),0) | G40: =$H$1430 | H40: =$I$1430 | I40: =$G$1430 | J40: =$H$1431 | K40: =$I$1431 | L40: =$G$1431 | M40: =$H$1432 | N40: =$I$1432 | O40: =$G$1432 | P40: =$H$1433 | Q40: =$I$1433 | R40: =$G$1433 | S40: =$H$1434 | T40: =$I$1434 | U40: =$G$1434 | V40: =$H$1435 | W40: =$I$1435 | X40: =$G$1435 | Z40: 1416
A41: RAG R1-R2-R3 | B41: gpt4-turbo-preview | C41: =COUNT($B$1474,$C$1474,$D$1474,$E$1474,$F$1474) | D41: =SUM($B$1484:$F$1484) | E41: =IFERROR(100*$D$41/($C$41*36),0) | F41: =IFERROR(1-$D$41/($C$41*36),0) | G41: =$H$1478 | H41: =$I$1478 | I41: =$G$1478 | J41: =$H$1479 | K41: =$I$1479 | L41: =$G$1479 | M41: =$H$1480 | N41: =$I$1480 | O41: =$G$1480 | P41: =$H$1481 | Q41: =$I$1481 | R41: =$G$1481 | S41: =$H$1482 | T41: =$I$1482 | U41: =$G$1482 | V41: =$H$1483 | W41: =$I$1483 | X41: =$G$1483 | Z41: 1464
A42: RAG R1-R2-R3 | B42: gpt4o | C42: 0 | G42: N/A | H42: N/A | I42: N/A | J42: N/A | K42: N/A | L42: N/A | M42: N/A | N42: N/A | O42: N/A | P42: N/A | Q42: N/A | R42: N/A | S42: N/A | T42: N/A | U42: N/A | V42: N/A | W42: N/A | X42: N/A | Y42: N/A
...

Sheet PS-i
A1: PS-i — metrics as spreadsheet formulas over the pasted run matrices (raw matrices)
A2: Rows 6–55: summary (all formulas referencing the blocks below). Rows 59–68: gold/silver ranking. Blocks from row 72: pasted run matrices, then every metric as a formula.
A5: Configuration | B5: Model | C5: n_runs | D5: unsure cells | E5: unsure % | F5: coverage | G5: Precision mean | H5: Precision std | I5: Precision avg-matrix | J5: Recall mean | K5: Recall std | L5: Recall avg-matrix | M5: F1 mean | N5: F1 std | O5: F1 avg-matrix | P5: Accuracy mean | Q5: Accuracy std | R5: Accuracy avg-matrix | S5: Edit distance mean | T5: Edit distance std | U5: Edit distance avg-matrix | V5: Spectral distance mean | W5: Spectral distance std | X5: Spectral distance avg-matrix | Y5: note | Z5: block row
A6: LLM | B6: gpt4-turbo-preview | C6: =COUNT($B$83,$C$83,$D$83,$E$83,$F$83) | D6: =SUM($B$93:$F$93) | E6: =IFERROR(100*$D$6/($C$6*49),0) | F6: =IFERROR(1-$D$6/($C$6*49),0) | G6: =$H$87 | H6: =$I$87 | I6: =$G$87 | J6: =$H$88 | K6: =$I$88 | L6: =$G$88 | M6: =$H$89 | N6: =$I$89 | O6: =$G$89 | P6: =$H$90 | Q6: =$I$90 | R6: =$G$90 | S6: =$H$91 | T6: =$I$91 | U6: =$G$91 | V6: =$H$92 | W6: =$I$92 | X6: =$G$92 | Z6: 72
A7: LLM | B7: gpt4o | C7: =COUNT($B$135,$C$135,$D$135,$E$135,$F$135) | D7: =SUM($B$145:$F$145) | E7: =IFERROR(100*$D$7/($C$7*49),0) | F7: =IFERROR(1-$D$7/($C$7*49),0) | G7: =$H$139 | H7: =$I$139 | I7: =$G$139 | J7: =$H$140 | K7: =$I$140 | L7: =$G$140 | M7: =$H$141 | N7: =$I$141 | O7: =$G$141 | P7: =$H$142 | Q7: =$I$142 | R7: =$G$142 | S7: =$H$143 | T7: =$I$143 | U7: =$G$143 | V7: =$H$144 | W7: =$I$144 | X7: =$G$144 | Z7: 124
A8: LLM | B8: mixtral:8x22b | C8: =COUNT($B$187,$C$187,$D$187,$E$187,$F$187) | D8: =SUM($B$197:$F$197) | E8: =IFERROR(100*$D$8/($C$8*49),0) | F8: =IFERROR(1-$D$8/($C$8*49),0) | G8: =$H$191 | H8: =$I$191 | I8: =$G$191 | J8: =$H$192 | K8: =$I$192 | L8: =$G$192 | M8: =$H$193 | N8: =$I$193 | O8: =$G$193 | P8: =$H$194 | Q8: =$I$194 | R8: =$G$194 | S8: =$H$195 | T8: =$I$195 | U8: =$G$195 | V8: =$H$196 | W8: =$I$196 | X8: =$G$196 | Z8: 176
A9: LLM | B9: llama3.3:70b | C9: =COUNT($B$239,$C$239,$D$239,$E$239,$F$239) | D9: =SUM($B$249:$F$249) | E9: =IFERROR(100*$D$9/($C$9*49),0) | F9: =IFERROR(1-$D$9/($C$9*49),0) | G9: =$H$243 | H9: =$I$243 | I9: =$G$243 | J9: =$H$244 | K9: =$I$244 | L9: =$G$244 | M9: =$H$245 | N9: =$I$245 | O9: =$G$245 | P9: =$H$246 | Q9: =$I$246 | R9: =$G$246 | S9: =$H$247 | T9: =$I$247 | U9: =$G$247 | V9: =$H$248 | W9: =$I$248 | X9: =$G$248 | Z9: 228
A10: LLM | B10: deepseek-r1:14b | C10: =COUNT($B$291,$C$291,$D$291,$E$291,$F$291) | D10: =SUM($B$301:$F$301) | E10: =IFERROR(100*$D$10/($C$10*49),0) | F10: =IFERROR(1-$D$10/($C$10*49),0) | G10: =$H$295 | H10: =$I$295 | I10: =$G$295 | J10: =$H$296 | K10: =$I$296 | L10: =$G$296 | M10: =$H$297 | N10: =$I$297 | O10: =$G$297 | P10: =$H$298 | Q10: =$I$298 | R10: =$G$298 | S10: =$H$299 | T10: =$I$299 | U10: =$G$299 | V10: =$H$300 | W10: =$I$300 | X10: =$G$300 | Z10: 280
A11: RAG R1 | B11: gpt4-turbo-preview | C11: =COUNT($B$343,$C$343,$D$343,$E$343,$F$343) | D11: =SUM($B$353:$F$353) | E11: =IFERROR(100*$D$11/($C$11*49),0) | F11: =IFERROR(1-$D$11/($C$11*49),0) | G11: =$H$347 | H11: =$I$347 | I11: =$G$347 | J11: =$H$348 | K11: =$I$348 | L11: =$G$348 | M11: =$H$349 | N11: =$I$349 | O11: =$G$349 | P11: =$H$350 | Q11: =$I$350 | R11: =$G$350 | S11: =$H$351 | T11: =$I$351 | U11: =$G$351 | V11: =$H$352 | W11: =$I$352 | X11: =$G$352 | Z11: 332
A12: RAG R1 | B12: gpt4o | C12: 0 | G12: N/A | H12: N/A | I12: N/A | J12: N/A | K12: N/A | L12: N/A | M12: N/A | N12: N/A | O12: N/A | P12: N/A | Q12: N/A | R12: N/A | S12: N/A | T12: N/A | U12: N/A | V12: N/A | W12: N/A | X12: N/A | Y12: N/A
A13: RAG R1 | B13: mixtral:8x22b | C13: =COUNT($B$395,$C$395,$D$395,$E$395,$F$395) | D13: =SUM($B$405:$F$405) | E13: =IFERROR(100*$D$13/($C$13*49),0) | F13: =IFERROR(1-$D$13/($C$13*49),0) | G13: =$H$399 | H13: =$I$399 | I13: =$G$399 | J13: =$H$400 | K13: =$I$400 | L13: =$G$400 | M13: =$H$401 | N13: =$I$401 | O13: =$G$401 | P13: =$H$402 | Q13: =$I$402 | R13: =$G$402 | S13: =$H$403 | T13: =$I$403 | U13: =$G$403 | V13: =$H$404 | W13: =$I$404 | X13: =$G$404 | Z13: 384
A14: RAG R1 | B14: llama3.3:70b | C14: =COUNT($B$447,$C$447,$D$447,$E$447,$F$447) | D14: =SUM($B$457:$F$457) | E14: =IFERROR(100*$D$14/($C$14*49),0) | F14: =IFERROR(1-$D$14/($C$14*49),0) | G14: =$H$451 | H14: =$I$451 | I14: =$G$451 | J14: =$H$452 | K14: =$I$452 | L14: =$G$452 | M14: =$H$453 | N14: =$I$453 | O14: =$G$453 | P14: =$H$454 | Q14: =$I$454 | R14: =$G$454 | S14: =$H$455 | T14: =$I$455 | U14: =$G$455 | V14: =$H$456 | W14: =$I$456 | X14: =$G$456 | Z14: 436
A15: RAG R1 | B15: deepseek-r1:14b | C15: =COUNT($B$499,$C$499,$D$499,$E$499,$F$499) | D15: =SUM($B$509:$F$509) | E15: =IFERROR(100*$D$15/($C$15*49),0) | F15: =IFERROR(1-$D$15/($C$15*49),0) | G15: =$H$503 | H15: =$I$503 | I15: =$G$503 | J15: =$H$504 | K15: =$I$504 | L15: =$G$504 | M15: =$H$505 | N15: =$I$505 | O15: =$G$505 | P15: =$H$506 | Q15: =$I$506 | R15: =$G$506 | S15: =$H$507 | T15: =$I$507 | U15: =$G$507 | V15: =$H$508 | W15: =$I$508 | X15: =$G$508 | Z15: 488
A16: RAG R2 | B16: gpt4-turbo-preview | C16: =COUNT($B$551,$C$551,$D$551,$E$551,$F$551) | D16: =SUM($B$561:$F$561) | E16: =IFERROR(100*$D$16/($C$16*49),0) | F16: =IFERROR(1-$D$16/($C$16*49),0) | G16: =$H$555 | H16: =$I$555 | I16: =$G$555 | J16: =$H$556 | K16: =$I$556 | L16: =$G$556 | M16: =$H$557 | N16: =$I$557 | O16: =$G$557 | P16: =$H$558 | Q16: =$I$558 | R16: =$G$558 | S16: =$H$559 | T16: =$I$559 | U16: =$G$559 | V16: =$H$560 | W16: =$I$560 | X16: =$G$560 | Z16: 540
A17: RAG R2 | B17: gpt4o | C17: 0 | G17: N/A | H17: N/A | I17: N/A | J17: N/A | K17: N/A | L17: N/A | M17: N/A | N17: N/A | O17: N/A | P17: N/A | Q17: N/A | R17: N/A | S17: N/A | T17: N/A | U17: N/A | V17: N/A | W17: N/A | X17: N/A | Y17: N/A
A18: RAG R2 | B18: mixtral:8x22b | C18: =COUNT($B$603,$C$603,$D$603,$E$603,$F$603) | D18: =SUM($B$613:$F$613) | E18: =IFERROR(100*$D$18/($C$18*49),0) | F18: =IFERROR(1-$D$18/($C$18*49),0) | G18: =$H$607 | H18: =$I$607 | I18: =$G$607 | J18: =$H$608 | K18: =$I$608 | L18: =$G$608 | M18: =$H$609 | N18: =$I$609 | O18: =$G$609 | P18: =$H$610 | Q18: =$I$610 | R18: =$G$610 | S18: =$H$611 | T18: =$I$611 | U18: =$G$611 | V18: =$H$612 | W18: =$I$612 | X18: =$G$612 | Z18: 592
A19: RAG R2 | B19: llama3.3:70b | C19: =COUNT($B$655,$C$655,$D$655,$E$655,$F$655) | D19: =SUM($B$665:$F$665) | E19: =IFERROR(100*$D$19/($C$19*49),0) | F19: =IFERROR(1-$D$19/($C$19*49),0) | G19: =$H$659 | H19: =$I$659 | I19: =$G$659 | J19: =$H$660 | K19: =$I$660 | L19: =$G$660 | M19: =$H$661 | N19: =$I$661 | O19: =$G$661 | P19: =$H$662 | Q19: =$I$662 | R19: =$G$662 | S19: =$H$663 | T19: =$I$663 | U19: =$G$663 | V19: =$H$664 | W19: =$I$664 | X19: =$G$664 | Z19: 644
A20: RAG R2 | B20: deepseek-r1:14b | C20: =COUNT($B$707,$C$707,$D$707,$E$707,$F$707) | D20: =SUM($B$717:$F$717) | E20: =IFERROR(100*$D$20/($C$20*49),0) | F20: =IFERROR(1-$D$20/($C$20*49),0) | G20: =$H$711 | H20: =$I$711 | I20: =$G$711 | J20: =$H$712 | K20: =$I$712 | L20: =$G$712 | M20: =$H$713 | N20: =$I$713 | O20: =$G$713 | P20: =$H$714 | Q20: =$I$714 | R20: =$G$714 | S20: =$H$715 | T20: =$I$715 | U20: =$G$715 | V20: =$H$716 | W20: =$I$716 | X20: =$G$716 | Z20: 696
A21: RAG R3 | B21: gpt4-turbo-preview | C21: =COUNT($B$759,$C$759,$D$759,$E$759,$F$759) | D21: =SUM($B$769:$F$769) | E21: =IFERROR(100*$D$21/($C$21*49),0) | F21: =IFERROR(1-$D$21/($C$21*49),0) | G21: =$H$763 | H21: =$I$763 | I21: =$G$763 | J21: =$H$764 | K21: =$I$764 | L21: =$G$764 | M21: =$H$765 | N21: =$I$765 | O21: =$G$765 | P21: =$H$766 | Q21: =$I$766 | R21: =$G$766 | S21: =$H$767 | T21: =$I$767 | U21: =$G$767 | V21: =$H$768 | W21: =$I$768 | X21: =$G$768 | Z21: 748
A22: RAG R3 | B22: gpt4o | C22: 0 | G22: N/A | H22: N/A | I22: N/A | J22: N/A | K22: N/A | L22: N/A | M22: N/A | N22: N/A | O22: N/A | P22: N/A | Q22: N/A | R22: N/A | S22: N/A | T22: N/A | U22: N/A | V22: N/A | W22: N/A | X22: N/A | Y22: N/A
A23: RAG R3 | B23: mixtral:8x22b | C23: =COUNT($B$811,$C$811,$D$811,$E$811,$F$811) | D23: =SUM($B$821:$F$821) | E23: =IFERROR(100*$D$23/($C$23*49),0) | F23: =IFERROR(1-$D$23/($C$23*49),0) | G23: =$H$815 | H23: =$I$815 | I23: =$G$815 | J23: =$H$816 | K23: =$I$816 | L23: =$G$816 | M23: =$H$817 | N23: =$I$817 | O23: =$G$817 | P23: =$H$818 | Q23: =$I$818 | R23: =$G$818 | S23: =$H$819 | T23: =$I$819 | U23: =$G$819 | V23: =$H$820 | W23: =$I$820 | X23: =$G$820 | Z23: 800
